Workbook

Sheet ALL
B1: Type | C1: JAN | D1: FEB | E1: MAR | F1: APR | G1: MAY | H1: JUN | I1: JUL | J1: AUG | K1: SEP | L1: OCT | M1: NOV | N1: DEC | O1: JAN'27 | P1: FEB'27 | Q1: MAR'27
A2: ALL | B2: Staff | C2: 148 | D2: 149 | E2: 149 | F2: 151 | G2: 150 | H2: 150 | I2: 149 | J2: 149 | K2: 149 | L2: 149 | M2: 149 | N2: 149 | O2: 149 | P2: 149 | Q2: 149
A3: ALL | B3: Staff AVG | C3: 149 | D3: 149 | E3: 149 | F3: 149 | G3: 149 | H3: 149 | I3: 149 | J3: 149 | K3: 149 | L3: 149 | M3: 149 | N3: 149 | O3: 149 | P3: 149 | Q3: 149
A4: ALL | B4: Plan | C4: 131 | D4: 139 | E4: 142 | F4: 143 | G4: 147 | H4: 144 | I4: 143 | J4: 140 | K4: 139 | L4: 132 | M4: 130 | N4: 130 | O4: 105 | P4: 104 | Q4: 104
B6: % Plan | C6: 0.8826 | D6: 0.9362 | E6: 0.9559 | F6: 0.9479 | G6: 0.9792 | H6: 0.9583 | I6: 0.9591 | J6: 0.9376 | K6: 0.9318 | L6: 0.8837 | M6: 0.8741 | N6: 0.8694 | O6: 0.7023 | P6: 0.7002 | Q6: 0.7002
B7: Available FTE | C7: 17 | D7: 10 | E7: 7 | F7: 8 | G7: 3 | H7: 6 | I7: 6 | J7: 9 | K7: 10 | L7: 17 | M7: 19 | N7: 19 | O7: 44 | P7: 45 | Q7: 45
A9: Staff | B9: PAYROLL | C9: 121 | D9: 120 | E9: 118 | F9: 118 | G9: 117 | H9: 117 | I9: 116 | J9: 116 | K9: 116 | L9: 116 | M9: 116 | N9: 116 | O9: 116 | P9: 116 | Q9: 116
A10: Staff AVG | B10: PAYROLL | C10: 117 | D10: 117 | E10: 117 | F10: 116 | G10: 116 | H10: 116 | I10: 116 | J10: 116 | K10: 116 | L10: 116 | M10: 116 | N10: 116 | O10: 116 | P10: 116 | Q10: 116
A11: Plan | B11: PAYROLL | C11: 105 | D11: 111 | E11: 111 | F11: 112 | G11: 113 | H11: 111 | I11: 108 | J11: 105 | K11: 103 | L11: 100 | M11: 99 | N11: 98 | O11: 81 | P11: 81 | Q11: 81
A13: Staff | B13: CONTRACTOR | C13: 21 | D13: 21 | E13: 21 | F13: 21 | G13: 21 | H13: 21 | I13: 21 | J13: 21 | K13: 21 | L13: 21 | M13: 21 | N13: 21 | O13: 21 | P13: 21 | Q13: 21
A14: Staff AVG | B14: CONTRACTOR | C14: 21 | D14: 21 | E14: 21 | F14: 21 | G14: 21 | H14: 21 | I14: 21 | J14: 21 | K14: 21 | L14: 21 | M14: 21 | N14: 21 | O14: 21 | P14: 21 | Q14: 21
A15: Plan | B15: CONTRACTOR | C15: 20 | D15: 20 | E15: 22 | F15: 21 | G15: 21 | H15: 20 | I15: 20 | J15: 20 | K15: 20 | L15: 19 | M15: 19 | N15: 19 | O15: 17 | P15: 17 | Q15: 17
A17: Staff | B17: OUTSOURCE | C17: 6 | D17: 8 | E17: 10 | F17: 12 | G17: 12 | H17: 12 | I17: 12 | J17: 12 | K17: 12 | L17: 12 | M17: 12 | N17: 12 | O17: 12 | P17: 12 | Q17: 12
A18: Staff AVG | B18: OUTSOURCE | C18: 11 | D18: 11 | E18: 11 | F18: 11 | G18: 11 | H18: 11 | I18: 11 | J18: 11 | K18: 11 | L18: 11 | M18: 11 | N18: 11 | O18: 11 | P18: 11 | Q18: 11
A19: Plan | B19: OUTSOURCE | C19: 6 | D19: 8 | E19: 10 | F19: 10 | G19: 12 | H19: 14 | I19: 15 | J19: 15 | K19: 16 | L19: 12 | M19: 12 | N19: 12 | O19: 7 | P19: 7 | Q19: 7
B31: Type | C31: Q1 | D31: Q2 | E31: Q3 | F31: Q4 | G31: Q1'27
A32: ALL | B32: Staff | C32: 149 | D32: 150 | E32: 149 | F32: 149 | G32: 149
A33: ALL | B33: Staff AVG | C33: 149 | D33: 149 | E33: 149 | F33: 149 | G33: 149
A34: ALL | B34: Plan | C34: 138 | D34: 145 | E34: 140 | F34: 130 | G34: 121
C35: 0.075 | D35: 0.0382 | E35: 0.0572 | F35: 0.1243 | G35: 0.1848
B36: % Plan | C36: 0.925 | D36: 0.9618 | E36: 0.9428 | F36: 0.8757 | G36: 0.8152
B37: Available FTE | C37: 11 | D37: 6 | E37: 9 | F37: 19 | G37: 28
A39: Staff | B39: PAYROLL | C39: 120 | D39: 117 | E39: 116 | F39: 116 | G39: 116
A40: Staff AVG | B40: PAYROLL | C40: 117 | D40: 116 | E40: 116 | F40: 116 | G40: 116
A41: Plan | B41: PAYROLL | C41: 109 | D41: 112 | E41: 105 | F41: 99 | G41: 93
A43: Staff | B43: CONTRACTOR | C43: 21 | D43: 21 | E43: 21 | F43: 21 | G43: 21
A44: Staff AVG | B44: CONTRACTOR | C44: 21 | D44: 21 | E44: 21 | F44: 21 | G44: 21
A45: Plan | B45: CONTRACTOR | C45: 21 | D45: 21 | E45: 20 | F45: 19 | G45: 18
A47: Staff | B47: OUTSOURCE | C47: 8 | D47: 12 | E47: 12 | F47: 12 | G47: 12
A48: Staff AVG | B48: OUTSOURCE | C48: 11 | D48: 11 | E48: 11 | F48: 11 | G48: 11
A49: Plan | B49: OUTSOURCE | C49: 8 | D49: 12 | E49: 15 | F49: 12 | G49: 11

Sheet GraphAll
B1: =IF(ALL!C1>0,ALL!C1,"") -> JAN | C1: =IF(ALL!D1>0,ALL!D1,"") -> FEB | D1: =IF(ALL!E1>0,ALL!E1,"") -> MAR | E1: =IF(ALL!F1>0,ALL!F1,"") -> APR | F1: =IF(ALL!G1>0,ALL!G1,"") -> MAY | G1: =IF(ALL!H1>0,ALL!H1,"") -> JUN | H1: =IF(ALL!I1>0,ALL!I1,"") -> JUL | I1: =IF(ALL!J1>0,ALL!J1,"") -> AUG | ... P1: =IF(ALL!Q1>0,ALL!Q1,"") -> MAR'27
A2: =IF(ALL!B2>0,ALL!B2,"") -> Staff | B2: =IF(ALL!C2>0,ALL!C2,"") -> 148 | C2: =IF(ALL!D2>0,ALL!D2,"") -> 149 | D2: =IF(ALL!E2>0,ALL!E2,"") -> 149 | E2: =IF(ALL!F2>0,ALL!F2,"") -> 151 | F2: =IF(ALL!G2>0,ALL!G2,"") -> 150 | G2: =IF(ALL!H2>0,ALL!H2,"") -> 150 | H2: =IF(ALL!I2>0,ALL!I2,"") -> 149 | ... P2: =IF(ALL!Q2>0,ALL!Q2,"") -> 149
A3: =IF(ALL!B3>0,ALL!B3,"") -> Staff AVG | B3: =IF(ALL!C3>0,ALL!C3,"") -> 149 | C3: =IF(ALL!D3>0,ALL!D3,"") -> 149 | D3: =IF(ALL!E3>0,ALL!E3,"") -> 149 | E3: =IF(ALL!F3>0,ALL!F3,"") -> 149 | F3: =IF(ALL!G3>0,ALL!G3,"") -> 149 | G3: =IF(ALL!H3>0,ALL!H3,"") -> 149 | H3: =IF(ALL!I3>0,ALL!I3,"") -> 149 | ... P3: =IF(ALL!Q3>0,ALL!Q3,"") -> 149
A4: =IF(ALL!B4>0,ALL!B4,"") -> Plan | B4: =IF(ALL!C4>0,ALL!C4,"") -> 131 | C4: =IF(ALL!D4>0,ALL!D4,"") -> 139 | D4: =IF(ALL!E4>0,ALL!E4,"") -> 142 | E4: =IF(ALL!F4>0,ALL!F4,"") -> 143 | F4: =IF(ALL!G4>0,ALL!G4,"") -> 147 | G4: =IF(ALL!H4>0,ALL!H4,"") -> 144 | H4: =IF(ALL!I4>0,ALL!I4,"") -> 143 | ... P4: =IF(ALL!Q4>0,ALL!Q4,"") -> 104
A5: =IF(ALL!B11>0,ALL!B11,"") -> PAYROLL | B5: =IF(ALL!C11>0,ALL!C11,"") -> 105 | C5: =IF(ALL!D11>0,ALL!D11,"") -> 111 | D5: =IF(ALL!E11>0,ALL!E11,"") -> 111 | E5: =IF(ALL!F11>0,ALL!F11,"") -> 112 | F5: =IF(ALL!G11>0,ALL!G11,"") -> 113 | G5: =IF(ALL!H11>0,ALL!H11,"") -> 111 | H5: =IF(ALL!I11>0,ALL!I11,"") -> 108 | ... P5: =IF(ALL!Q11>0,ALL!Q11,"") -> 81
A6: =IF(ALL!B15>0,ALL!B15,"") -> CONTRACTOR | B6: =IF(ALL!C15>0,ALL!C15,"") -> 20 | C6: =IF(ALL!D15>0,ALL!D15,"") -> 20 | D6: =IF(ALL!E15>0,ALL!E15,"") -> 22 | E6: =IF(ALL!F15>0,ALL!F15,"") -> 21 | F6: =IF(ALL!G15>0,ALL!G15,"") -> 21 | G6: =IF(ALL!H15>0,ALL!H15,"") -> 20 | H6: =IF(ALL!I15>0,ALL!I15,"") -> 20 | ... P6: =IF(ALL!Q15>0,ALL!Q15,"") -> 17
A7: =IF(ALL!B19>0,ALL!B19,"") -> OUTSOURCE | B7: =IF(ALL!C19>0,ALL!C19,"") -> 6 | C7: =IF(ALL!D19>0,ALL!D19,"") -> 8 | D7: =IF(ALL!E19>0,ALL!E19,"") -> 10 | E7: =IF(ALL!F19>0,ALL!F19,"") -> 10 | F7: =IF(ALL!G19>0,ALL!G19,"") -> 12 | G7: =IF(ALL!H19>0,ALL!H19,"") -> 14 | H7: =IF(ALL!I19>0,ALL!I19,"") -> 15 | ... P7: =IF(ALL!Q19>0,ALL!Q19,"") -> 7
B11: =IF(ALL!C1>0,ALL!C1,"") -> JAN | C11: =IF(ALL!D1>0,ALL!D1,"") -> FEB | D11: =IF(ALL!E1>0,ALL!E1,"") -> MAR | E11: =IF(ALL!F1>0,ALL!F1,"") -> APR | F11: =IF(ALL!G1>0,ALL!G1,"") -> MAY | G11: =IF(ALL!H1>0,ALL!H1,"") -> JUN | H11: =IF(ALL!I1>0,ALL!I1,"") -> JUL | I11: =IF(ALL!J1>0,ALL!J1,"") -> AUG | ... P11: =IF(ALL!Q1>0,ALL!Q1,"") -> MAR'27
A12: =IF(ALL!A9>0,ALL!A9,"") -> Staff | B12: =IF(ALL!C9>0,ALL!C9,"") -> 121 | C12: =IF(ALL!D9>0,ALL!D9,"") -> 120 | D12: =IF(ALL!E9>0,ALL!E9,"") -> 118 | E12: =IF(ALL!F9>0,ALL!F9,"") -> 118 | F12: =IF(ALL!G9>0,ALL!G9,"") -> 117 | G12: =IF(ALL!H9>0,ALL!H9,"") -> 117 | H12: =IF(ALL!I9>0,ALL!I9,"") -> 116 | I12: =IF(ALL!J9>0,ALL!J9,"") -> 116 | ... P12: =IF(ALL!Q9>0,ALL!Q9,"") -> 116
A13: =IF(ALL!A10>0,ALL!A10,"") -> Staff AVG | B13: =IF(ALL!C10>0,ALL!C10,"") -> 117 | C13: =IF(ALL!D10>0,ALL!D10,"") -> 117 | D13: =IF(ALL!E10>0,ALL!E10,"") -> 117 | E13: =IF(ALL!F10>0,ALL!F10,"") -> 116 | F13: =IF(ALL!G10>0,ALL!G10,"") -> 116 | G13: =IF(ALL!H10>0,ALL!H10,"") -> 116 | H13: =IF(ALL!I10>0,ALL!I10,"") -> 116 | I13: =IF(ALL!J10>0,ALL!J10,"") -> 116 | ... P13: =IF(ALL!Q10>0,ALL!Q10,"") -> 116
A14: =IF(ALL!A11>0,ALL!A11,"") -> Plan | B14: =IF(ALL!C11>0,ALL!C11,"") -> 105 | C14: =IF(ALL!D11>0,ALL!D11,"") -> 111 | D14: =IF(ALL!E11>0,ALL!E11,"") -> 111 | E14: =IF(ALL!F11>0,ALL!F11,"") -> 112 | F14: =IF(ALL!G11>0,ALL!G11,"") -> 113 | G14: =IF(ALL!H11>0,ALL!H11,"") -> 111 | H14: =IF(ALL!I11>0,ALL!I11,"") -> 108 | I14: =IF(ALL!J11>0,ALL!J11,"") -> 105 | ... P14: =IF(ALL!Q11>0,ALL!Q11,"") -> 81
B21: =IF(ALL!C1>0,ALL!C1,"") -> JAN | C21: =IF(ALL!D1>0,ALL!D1,"") -> FEB | D21: =IF(ALL!E1>0,ALL!E1,"") -> MAR | E21: =IF(ALL!F1>0,ALL!F1,"") -> APR | F21: =IF(ALL!G1>0,ALL!G1,"") -> MAY | G21: =IF(ALL!H1>0,ALL!H1,"") -> JUN | H21: =IF(ALL!I1>0,ALL!I1,"") -> JUL | I21: =IF(ALL!J1>0,ALL!J1,"") -> AUG | ... P21: =IF(ALL!Q1>0,ALL!Q1,"") -> MAR'27
A22: =IF(ALL!A13>0,ALL!A13,"") -> Staff | B22: =IF(ALL!C13>0,ALL!C13,"") -> 21 | C22: =IF(ALL!D13>0,ALL!D13,"") -> 21 | D22: =IF(ALL!E13>0,ALL!E13,"") -> 21 | E22: =IF(ALL!F13>0,ALL!F13,"") -> 21 | F22: =IF(ALL!G13>0,ALL!G13,"") -> 21 | G22: =IF(ALL!H13>0,ALL!H13,"") -> 21 | H22: =IF(ALL!I13>0,ALL!I13,"") -> 21 | I22: =IF(ALL!J13>0,ALL!J13,"") -> 21 | ... P22: =IF(ALL!Q13>0,ALL!Q13,"") -> 21
A23: =IF(ALL!A14>0,ALL!A14,"") -> Staff AVG | B23: =IF(ALL!C14>0,ALL!C14,"") -> 21 | C23: =IF(ALL!D14>0,ALL!D14,"") -> 21 | D23: =IF(ALL!E14>0,ALL!E14,"") -> 21 | E23: =IF(ALL!F14>0,ALL!F14,"") -> 21 | F23: =IF(ALL!G14>0,ALL!G14,"") -> 21 | G23: =IF(ALL!H14>0,ALL!H14,"") -> 21 | H23: =IF(ALL!I14>0,ALL!I14,"") -> 21 | I23: =IF(ALL!J14>0,ALL!J14,"") -> 21 | ... P23: =IF(ALL!Q14>0,ALL!Q14,"") -> 21
A24: =IF(ALL!A15>0,ALL!A15,"") -> Plan | B24: =IF(ALL!C15>0,ALL!C15,"") -> 20 | C24: =IF(ALL!D15>0,ALL!D15,"") -> 20 | D24: =IF(ALL!E15>0,ALL!E15,"") -> 22 | E24: =IF(ALL!F15>0,ALL!F15,"") -> 21 | F24: =IF(ALL!G15>0,ALL!G15,"") -> 21 | G24: =IF(ALL!H15>0,ALL!H15,"") -> 20 | H24: =IF(ALL!I15>0,ALL!I15,"") -> 20 | I24: =IF(ALL!J15>0,ALL!J15,"") -> 20 | ... P24: =IF(ALL!Q15>0,ALL!Q15,"") -> 17
B31: =IF(ALL!C1>0,ALL!C1,"") -> JAN | C31: =IF(ALL!D1>0,ALL!D1,"") -> FEB | D31: =IF(ALL!E1>0,ALL!E1,"") -> MAR | E31: =IF(ALL!F1>0,ALL!F1,"") -> APR | F31: =IF(ALL!G1>0,ALL!G1,"") -> MAY | G31: =IF(ALL!H1>0,ALL!H1,"") -> JUN | H31: =IF(ALL!I1>0,ALL!I1,"") -> JUL | I31: =IF(ALL!J1>0,ALL!J1,"") -> AUG | ... P31: =IF(ALL!Q1>0,ALL!Q1,"") -> MAR'27
A32: =IF(ALL!A17>0,ALL!A17,"") -> Staff | B32: =IF(ALL!C17>0,ALL!C17,"") -> 6 | C32: =IF(ALL!D17>0,ALL!D17,"") -> 8 | D32: =IF(ALL!E17>0,ALL!E17,"") -> 10 | E32: =IF(ALL!F17>0,ALL!F17,"") -> 12 | F32: =IF(ALL!G17>0,ALL!G17,"") -> 12 | G32: =IF(ALL!H17>0,ALL!H17,"") -> 12 | H32: =IF(ALL!I17>0,ALL!I17,"") -> 12 | I32: =IF(ALL!J17>0,ALL!J17,"") -> 12 | ... P32: =IF(ALL!Q17>0,ALL!Q17,"") -> 12
A33: =IF(ALL!A18>0,ALL!A18,"") -> Staff AVG | B33: =IF(ALL!C18>0,ALL!C18,"") -> 11 | C33: =IF(ALL!D18>0,ALL!D18,"") -> 11 | D33: =IF(ALL!E18>0,ALL!E18,"") -> 11 | E33: =IF(ALL!F18>0,ALL!F18,"") -> 11 | F33: =IF(ALL!G18>0,ALL!G18,"") -> 11 | G33: =IF(ALL!H18>0,ALL!H18,"") -> 11 | H33: =IF(ALL!I18>0,ALL!I18,"") -> 11 | I33: =IF(ALL!J18>0,ALL!J18,"") -> 11 | ... P33: =IF(ALL!Q18>0,ALL!Q18,"") -> 11
A34: =IF(ALL!A19>0,ALL!A19,"") -> Plan | B34: =IF(ALL!C19>0,ALL!C19,"") -> 6 | C34: =IF(ALL!D19>0,ALL!D19,"") -> 8 | D34: =IF(ALL!E19>0,ALL!E19,"") -> 10 | E34: =IF(ALL!F19>0,ALL!F19,"") -> 10 | F34: =IF(ALL!G19>0,ALL!G19,"") -> 12 | G34: =IF(ALL!H19>0,ALL!H19,"") -> 14 | H34: =IF(ALL!I19>0,ALL!I19,"") -> 15 | I34: =IF(ALL!J19>0,ALL!J19,"") -> 15 | ... P34: =IF(ALL!Q19>0,ALL!Q19,"") -> 7
B41: =IF(ALL!C31>0,ALL!C31,"") -> Q1 | C41: =IF(ALL!D31>0,ALL!D31,"") -> Q2 | D41: =IF(ALL!E31>0,ALL!E31,"") -> Q3 | E41: =IF(ALL!F31>0,ALL!F31,"") -> Q4 | F41: =IF(ALL!G31>0,ALL!G31,"") -> Q1'27
A42: =IF(ALL!B32>0,ALL!B32,"") -> Staff | B42: =IF(ALL!C32>0,ALL!C32,"") -> 149 | C42: =IF(ALL!D32>0,ALL!D32,"") -> 150 | D42: =IF(ALL!E32>0,ALL!E32,"") -> 149 | E42: =IF(ALL!F32>0,ALL!F32,"") -> 149 | F42: =IF(ALL!G32>0,ALL!G32,"") -> 149
A43: =IF(ALL!B33>0,ALL!B33,"") -> Staff AVG | B43: =IF(ALL!C33>0,ALL!C33,"") -> 149 | C43: =IF(ALL!D33>0,ALL!D33,"") -> 149 | D43: =IF(ALL!E33>0,ALL!E33,"") -> 149 | E43: =IF(ALL!F33>0,ALL!F33,"") -> 149 | F43: =IF(ALL!G33>0,ALL!G33,"") -> 149
A44: =IF(ALL!B34>0,ALL!B34,"") -> Plan | B44: =IF(ALL!C34>0,ALL!C34,"") -> 138 | C44: =IF(ALL!D34>0,ALL!D34,"") -> 145 | D44: =IF(ALL!E34>0,ALL!E34,"") -> 140 | E44: =IF(ALL!F34>0,ALL!F34,"") -> 130 | F44: =IF(ALL!G34>0,ALL!G34,"") -> 121
A45: =IF(ALL!B41>0,ALL!B41,"") -> PAYROLL | B45: =IF(ALL!C41>0,ALL!C41,"") -> 109 | C45: =IF(ALL!D41>0,ALL!D41,"") -> 112 | D45: =IF(ALL!E41>0,ALL!E41,"") -> 105 | E45: =IF(ALL!F41>0,ALL!F41,"") -> 99 | F45: =IF(ALL!G41>0,ALL!G41,"") -> 93
A46: =IF(ALL!B45>0,ALL!B45,"") -> CONTRACTOR | B46: =IF(ALL!C45>0,ALL!C45,"") -> 21 | C46: =IF(ALL!D45>0,ALL!D45,"") -> 21 | D46: =IF(ALL!E45>0,ALL!E45,"") -> 20 | E46: =IF(ALL!F45>0,ALL!F45,"") -> 19 | F46: =IF(ALL!G45>0,ALL!G45,"") -> 18
A47: =IF(ALL!B49>0,ALL!B49,"") -> OUTSOURCE | B47: =IF(ALL!C49>0,ALL!C49,"") -> 8 | C47: =IF(ALL!D49>0,ALL!D49,"") -> 12 | D47: =IF(ALL!E49>0,ALL!E49,"") -> 15 | E47: =IF(ALL!F49>0,ALL!F49,"") -> 12 | F47: =IF(ALL!G49>0,ALL!G49,"") -> 11
B151: =ALL!C1 -> JAN | C151: =ALL!D1 -> FEB | D151: =ALL!E1 -> MAR | E151: =ALL!F1 -> APR | F151: =ALL!G1 -> MAY | G151: =ALL!H1 -> JUN | H151: =ALL!I1 -> JUL | I151: =ALL!J1 -> AUG | ... P151: =ALL!Q1 -> MAR'27
A152: =ALL!B6 -> % Plan | B152: =ALL!C6 -> 0.8826 | C152: =ALL!D6 -> 0.9362 | D152: =ALL!E6 -> 0.9559 | E152: =ALL!F6 -> 0.9479 | F152: =ALL!G6 -> 0.9792 | G152: =ALL!H6 -> 0.9583 | H152: =ALL!I6 -> 0.9591 | ... P152: =ALL!Q6 -> 0.7002
A153: =ALL!B7 -> Available FTE | B153: =ALL!C7 -> 17 | C153: =ALL!D7 -> 10 | D153: =ALL!E7 -> 7 | E153: =ALL!F7 -> 8 | F153: =ALL!G7 -> 3 | G153: =ALL!H7 -> 6 | H153: =ALL!I7 -> 6 | ... P153: =ALL!Q7 -> 45

Sheet CPS
B1: Type | C1: JAN | D1: FEB | E1: MAR | F1: APR | G1: MAY | H1: JUN | I1: JUL | J1: AUG | K1: SEP | L1: OCT | M1: NOV | N1: DEC | O1: JAN'27 | P1: FEB'27 | Q1: MAR'27
A2: CPS | B2: Staff | C2: 18 | D2: 18 | E2: 18 | F2: 17 | G2: 17 | H2: 17 | I2: 17 | J2: 17 | K2: 17 | L2: 17 | M2: 17 | N2: 17 | O2: 17 | P2: 17 | Q2: 17
A3: CPS | B3: Staff AVG | C3: 17 | D3: 17 | E3: 17 | F3: 17 | G3: 17 | H3: 17 | I3: 17 | J3: 17 | K3: 17 | L3: 17 | M3: 17 | N3: 17 | O3: 17 | P3: 17 | Q3: 17
A4: CPS | B4: Plan | C4: 17 | D4: 17 | E4: 17 | F4: 17 | G4: 18 | H4: 17 | I4: 16 | J4: 16 | K4: 16 | L4: 16 | M4: 16 | N4: 16 | O4: 14 | P4: 14 | Q4: 14
B6: % Plan | C6: 0.9361 | D6: 0.9417 | E6: 0.925 | F6: 1.0235 | G6: 1.0294 | H6: 1.0235 | I6: 0.9529 | J6: 0.9412 | K6: 0.9412 | L6: 0.9353 | M6: 0.9235 | N6: 0.9235 | O6: 0.8353 | P6: 0.8353 | Q6: 0.8353
B7: Available FTE | C7: 1 | D7: 1 | E7: 1 | F7: 0 | G7: 0 | H7: 0 | I7: 1 | J7: 1 | K7: 1 | L7: 1 | M7: 1 | N7: 1 | O7: 3 | P7: 3 | Q7: 3
A9: Staff | B9: PAYROLL | C9: 18 | D9: 18 | E9: 18 | F9: 17 | G9: 17 | H9: 17 | I9: 17 | J9: 17 | K9: 17 | L9: 17 | M9: 17 | N9: 17 | O9: 17 | P9: 17 | Q9: 17
A10: Staff AVG | B10: PAYROLL | C10: 17 | D10: 17 | E10: 17 | F10: 17 | G10: 17 | H10: 17 | I10: 17 | J10: 17 | K10: 17 | L10: 17 | M10: 17 | N10: 17 | O10: 17 | P10: 17 | Q10: 17
A11: Plan | B11: PAYROLL | C11: 17 | D11: 17 | E11: 17 | F11: 17 | G11: 18 | H11: 17 | I11: 16 | J11: 16 | K11: 16 | L11: 16 | M11: 16 | N11: 16 | O11: 14 | P11: 14 | Q11: 14
A13: Grand Total | B13: CONTRACTOR | C13: 0 | D13: 0 | E13: 0 | F13: 0 | G13: 0 | H13: 0 | I13: 0 | J13: 0 | K13: 0 | L13: 0 | M13: 0 | N13: 0 | O13: 0 | P13: 0 | Q13: 0
A14: Staff AVG | B14: CONTRACTOR | C14: 0 | D14: 0 | E14: 0 | F14: 0 | G14: 0 | H14: 0 | I14: 0 | J14: 0 | K14: 0 | L14: 0 | M14: 0 | N14: 0 | O14: 0 | P14: 0 | Q14: 0
A15: 0 | B15: CONTRACTOR | C15: 0 | D15: 0 | E15: 0 | F15: 0 | G15: 0 | H15: 0 | I15: 0 | J15: 0 | K15: 0 | L15: 0 | M15: 0 | N15: 0 | O15: 0 | P15: 0 | Q15: 0
A17: Grand Total | B17: OUTSOURCE | C17: 0 | D17: 0 | E17: 0 | F17: 0 | G17: 0 | H17: 0 | I17: 0 | J17: 0 | K17: 0 | L17: 0 | M17: 0 | N17: 0 | O17: 0 | P17: 0 | Q17: 0
A18: Staff AVG | B18: OUTSOURCE | C18: 0 | D18: 0 | E18: 0 | F18: 0 | G18: 0 | H18: 0 | I18: 0 | J18: 0 | K18: 0 | L18: 0 | M18: 0 | N18: 0 | O18: 0 | P18: 0 | Q18: 0
A19: 0 | B19: OUTSOURCE | C19: 0 | D19: 0 | E19: 0 | F19: 0 | G19: 0 | H19: 0 | I19: 0 | J19: 0 | K19: 0 | L19: 0 | M19: 0 | N19: 0 | O19: 0 | P19: 0 | Q19: 0
B31: Type | C31: Q1 | D31: Q2 | E31: Q3 | F31: Q4 | G31: Q1'27
A32: CPS | B32: Staff | C32: 18 | D32: 17 | E32: 17 | F32: 17 | G32: 17
A33: CPS | B33: Staff AVG | C33: 17 | D33: 17 | E33: 17 | F33: 17 | G33: 17
A34: CPS | B34: Plan | C34: 17 | D34: 17 | E34: 16 | F34: 16 | G34: 15
C35: 0.0657 | D35: -0.0255 | E35: 0.0549 | F35: 0.0725 | G35: 0.1059
B36: % Plan | C36: 0.9343 | D36: 1.0255 | E36: 0.9451 | F36: 0.9275 | G36: 0.8941
B37: Available FTE | C37: 1 | D37: 0 | E37: 1 | F37: 1 | G37: 2
A39: Staff | B39: PAYROLL | C39: 18 | D39: 17 | E39: 17 | F39: 17 | G39: 17
A40: Staff AVG | B40: PAYROLL | C40: 17 | D40: 17 | E40: 17 | F40: 17 | G40: 17
A41: Plan | B41: PAYROLL | C41: 17 | D41: 17 | E41: 16 | F41: 16 | G41: 15
A43: Grand Total | B43: CONTRACTOR | C43: 0 | D43: 0 | E43: 0 | F43: 0 | G43: 0
A44: Staff AVG | B44: CONTRACTOR | C44: 0 | D44: 0 | E44: 0 | F44: 0 | G44: 0
A45: 0 | B45: CONTRACTOR | C45: 0 | D45: 0 | E45: 0 | F45: 0 | G45: 0
A47: Grand Total | B47: OUTSOURCE | C47: 0 | D47: 0 | E47: 0 | F47: 0 | G47: 0
A48: Staff AVG | B48: OUTSOURCE | C48: 0 | D48: 0 | E48: 0 | F48: 0 | G48: 0
A49: 0 | B49: OUTSOURCE | C49: 0 | D49: 0 | E49: 0 | F49: 0 | G49: 0
A61: Section | C61: JAN | D61: FEB | E61: MAR | F61: APR | G61: MAY | H61: JUN | I61: JUL | J61: AUG | K61: SEP | L61: OCT | M61: NOV | N61: DEC | O61: JAN'27 | P61: FEB'27 | Q61: MAR'27
B62: Staff | C62: 18 | D62: 18 | E62: 18 | F62: 17 | G62: 17 | H62: 17 | I62: 17 | J62: 17 | K62: 17 | L62: 17 | M62: 17 | N62: 17 | O62: 17 | P62: 17 | Q62: 17
B63: Plan | C63: 16.85 | D63: 16.95 | E63: 16.65 | F63: 17.4 | G63: 17.5 | H63: 17.4 | I63: 16.2 | J63: 16 | K63: 16 | L63: 15.9 | M63: 15.7 | N63: 15.7 | O63: 14.2 | P63: 14.2 | Q63: 14.2
A64: Commercial Products & Solutions | B64: Staff | C64: 1 | D64: 1 | E64: 1 | F64: 1 | G64: 1 | H64: 1 | I64: 1 | J64: 1 | K64: 1 | L64: 1 | M64: 1 | N64: 1 | O64: 1 | P64: 1 | Q64: 1
A65: Commercial Products & Solutions | B65: Plan | C65: 1 | D65: 1 | E65: 1 | F65: 1 | G65: 1 | H65: 1 | I65: 1 | J65: 1 | K65: 1 | L65: 1 | M65: 1 | N65: 1 | O65: 1 | P65: 1 | Q65: 1
A66: Business Development & Partnerships | B66: Staff | C66: 12 | D66: 12 | E66: 12 | F66: 11 | G66: 11 | H66: 11 | I66: 11 | J66: 11 | K66: 11 | L66: 11 | M66: 11 | N66: 11 | O66: 11 | P66: 11 | Q66: 11
A67: Business Development & Partnerships | B67: Plan | C67: 11.25 | D67: 11.35 | E67: 11.05 | F67: 11.4 | G67: 11.5 | H67: 11.4 | I67: 10.2 | J67: 10 | K67: 10 | L67: 9.9 | M67: 9.7 | N67: 9.7 | O67: 8.2 | P67: 8.2 | Q67: 8.2
A68: Product Commercialization | B68: Staff | C68: 5 | D68: 5 | E68: 5 | F68: 5 | G68: 5 | H68: 5 | I68: 5 | J68: 5 | K68: 5 | L68: 5 | M68: 5 | N68: 5 | O68: 5 | P68: 5 | Q68: 5
A69: Product Commercialization | B69: Plan | C69: 4.6 | D69: 4.6 | E69: 4.6 | F69: 5 | G69: 5 | H69: 5 | I69: 5 | J69: 5 | K69: 5 | L69: 5 | M69: 5 | N69: 5 | O69: 5 | P69: 5 | Q69: 5

Sheet GraphCPS
B1: =IF(CPS!C1>0,CPS!C1,"") -> JAN | C1: =IF(CPS!D1>0,CPS!D1,"") -> FEB | D1: =IF(CPS!E1>0,CPS!E1,"") -> MAR | E1: =IF(CPS!F1>0,CPS!F1,"") -> APR | F1: =IF(CPS!G1>0,CPS!G1,"") -> MAY | G1: =IF(CPS!H1>0,CPS!H1,"") -> JUN | H1: =IF(CPS!I1>0,CPS!I1,"") -> JUL | I1: =IF(CPS!J1>0,CPS!J1,"") -> AUG | ... P1: =IF(CPS!Q1>0,CPS!Q1,"") -> MAR'27
A2: =IF(CPS!B2>0,CPS!B2,"") -> Staff | B2: =IF(CPS!C2>0,CPS!C2,"") -> 18 | C2: =IF(CPS!D2>0,CPS!D2,"") -> 18 | D2: =IF(CPS!E2>0,CPS!E2,"") -> 18 | E2: =IF(CPS!F2>0,CPS!F2,"") -> 17 | F2: =IF(CPS!G2>0,CPS!G2,"") -> 17 | G2: =IF(CPS!H2>0,CPS!H2,"") -> 17 | H2: =IF(CPS!I2>0,CPS!I2,"") -> 17 | ... P2: =IF(CPS!Q2>0,CPS!Q2,"") -> 17
A3: =IF(CPS!B3>0,CPS!B3,"") -> Staff AVG | B3: =IF(CPS!C3>0,CPS!C3,"") -> 17 | C3: =IF(CPS!D3>0,CPS!D3,"") -> 17 | D3: =IF(CPS!E3>0,CPS!E3,"") -> 17 | E3: =IF(CPS!F3>0,CPS!F3,"") -> 17 | F3: =IF(CPS!G3>0,CPS!G3,"") -> 17 | G3: =IF(CPS!H3>0,CPS!H3,"") -> 17 | H3: =IF(CPS!I3>0,CPS!I3,"") -> 17 | ... P3: =IF(CPS!Q3>0,CPS!Q3,"") -> 17
A4: =IF(CPS!B4>0,CPS!B4,"") -> Plan | B4: =IF(CPS!C4>0,CPS!C4,"") -> 17 | C4: =IF(CPS!D4>0,CPS!D4,"") -> 17 | D4: =IF(CPS!E4>0,CPS!E4,"") -> 17 | E4: =IF(CPS!F4>0,CPS!F4,"") -> 17 | F4: =IF(CPS!G4>0,CPS!G4,"") -> 18 | G4: =IF(CPS!H4>0,CPS!H4,"") -> 17 | H4: =IF(CPS!I4>0,CPS!I4,"") -> 16 | ... P4: =IF(CPS!Q4>0,CPS!Q4,"") -> 14
A5: =IF(CPS!B11>0,CPS!B11,"") -> PAYROLL | B5: =IF(CPS!C11>0,CPS!C11,"") -> 17 | C5: =IF(CPS!D11>0,CPS!D11,"") -> 17 | D5: =IF(CPS!E11>0,CPS!E11,"") -> 17 | E5: =IF(CPS!F11>0,CPS!F11,"") -> 17 | F5: =IF(CPS!G11>0,CPS!G11,"") -> 18 | G5: =IF(CPS!H11>0,CPS!H11,"") -> 17 | H5: =IF(CPS!I11>0,CPS!I11,"") -> 16 | ... P5: =IF(CPS!Q11>0,CPS!Q11,"") -> 14
A6: =IF(CPS!B15>0,CPS!B15,"") -> CONTRACTOR | B6: =IF(CPS!C15>0,CPS!C15,"") | C6: =IF(CPS!D15>0,CPS!D15,"") | D6: =IF(CPS!E15>0,CPS!E15,"") | E6: =IF(CPS!F15>0,CPS!F15,"") | F6: =IF(CPS!G15>0,CPS!G15,"") | G6: =IF(CPS!H15>0,CPS!H15,"") | H6: =IF(CPS!I15>0,CPS!I15,"") | ... P6: =IF(CPS!Q15>0,CPS!Q15,"")
A7: =IF(CPS!B19>0,CPS!B19,"") -> OUTSOURCE | B7: =IF(CPS!C19>0,CPS!C19,"") | C7: =IF(CPS!D19>0,CPS!D19,"") | D7: =IF(CPS!E19>0,CPS!E19,"") | E7: =IF(CPS!F19>0,CPS!F19,"") | F7: =IF(CPS!G19>0,CPS!G19,"") | G7: =IF(CPS!H19>0,CPS!H19,"") | H7: =IF(CPS!I19>0,CPS!I19,"") | ... P7: =IF(CPS!Q19>0,CPS!Q19,"")
B11: =IF(CPS!C1>0,CPS!C1,"") -> JAN | C11: =IF(CPS!D1>0,CPS!D1,"") -> FEB | D11: =IF(CPS!E1>0,CPS!E1,"") -> MAR | E11: =IF(CPS!F1>0,CPS!F1,"") -> APR | F11: =IF(CPS!G1>0,CPS!G1,"") -> MAY | G11: =IF(CPS!H1>0,CPS!H1,"") -> JUN | H11: =IF(CPS!I1>0,CPS!I1,"") -> JUL | I11: =IF(CPS!J1>0,CPS!J1,"") -> AUG | ... P11: =IF(CPS!Q1>0,CPS!Q1,"") -> MAR'27
A12: =IF(CPS!B2>0,CPS!B2,"") -> Staff | B12: =IF(CPS!C9>0,CPS!C9,"") -> 18 | C12: =IF(CPS!D9>0,CPS!D9,"") -> 18 | D12: =IF(CPS!E9>0,CPS!E9,"") -> 18 | E12: =IF(CPS!F9>0,CPS!F9,"") -> 17 | F12: =IF(CPS!G9>0,CPS!G9,"") -> 17 | G12: =IF(CPS!H9>0,CPS!H9,"") -> 17 | H12: =IF(CPS!I9>0,CPS!I9,"") -> 17 | I12: =IF(CPS!J9>0,CPS!J9,"") -> 17 | ... P12: =IF(CPS!Q9>0,CPS!Q9,"") -> 17
A13: =IF(CPS!B3>0,CPS!B3,"") -> Staff AVG | B13: =IF(CPS!C10>0,CPS!C10,"") -> 17 | C13: =IF(CPS!D10>0,CPS!D10,"") -> 17 | D13: =IF(CPS!E10>0,CPS!E10,"") -> 17 | E13: =IF(CPS!F10>0,CPS!F10,"") -> 17 | F13: =IF(CPS!G10>0,CPS!G10,"") -> 17 | G13: =IF(CPS!H10>0,CPS!H10,"") -> 17 | H13: =IF(CPS!I10>0,CPS!I10,"") -> 17 | I13: =IF(CPS!J10>0,CPS!J10,"") -> 17 | ... P13: =IF(CPS!Q10>0,CPS!Q10,"") -> 17
A14: =IF(CPS!B4>0,CPS!B4,"") -> Plan | B14: =IF(CPS!C11>0,CPS!C11,"") -> 17 | C14: =IF(CPS!D11>0,CPS!D11,"") -> 17 | D14: =IF(CPS!E11>0,CPS!E11,"") -> 17 | E14: =IF(CPS!F11>0,CPS!F11,"") -> 17 | F14: =IF(CPS!G11>0,CPS!G11,"") -> 18 | G14: =IF(CPS!H11>0,CPS!H11,"") -> 17 | H14: =IF(CPS!I11>0,CPS!I11,"") -> 16 | I14: =IF(CPS!J11>0,CPS!J11,"") -> 16 | ... P14: =IF(CPS!Q11>0,CPS!Q11,"") -> 14
B21: =IF(CPS!C1>0,CPS!C1,"") -> JAN | C21: =IF(CPS!D1>0,CPS!D1,"") -> FEB | D21: =IF(CPS!E1>0,CPS!E1,"") -> MAR | E21: =IF(CPS!F1>0,CPS!F1,"") -> APR | F21: =IF(CPS!G1>0,CPS!G1,"") -> MAY | G21: =IF(CPS!H1>0,CPS!H1,"") -> JUN | H21: =IF(CPS!I1>0,CPS!I1,"") -> JUL | I21: =IF(CPS!J1>0,CPS!J1,"") -> AUG | ... P21: =IF(CPS!Q1>0,CPS!Q1,"") -> MAR'27
A22: =CPS!B2 -> Staff | B22: =CPS!C13 -> 0 | C22: =CPS!D13 -> 0 | D22: =CPS!E13 -> 0 | E22: =CPS!F13 -> 0 | F22: =CPS!G13 -> 0 | G22: =CPS!H13 -> 0 | H22: =CPS!I13 -> 0 | I22: =CPS!J13 -> 0 | ... P22: =CPS!Q13 -> 0
A23: =CPS!B3 -> Staff AVG | B23: =CPS!C14 -> 0 | C23: =CPS!D14 -> 0 | D23: =CPS!E14 -> 0 | E23: =CPS!F14 -> 0 | F23: =CPS!G14 -> 0 | G23: =CPS!H14 -> 0 | H23: =CPS!I14 -> 0 | I23: =CPS!J14 -> 0 | ... P23: =CPS!Q14 -> 0
A24: =CPS!B4 -> Plan | B24: =CPS!C15 -> 0 | C24: =CPS!D15 -> 0 | D24: =CPS!E15 -> 0 | E24: =CPS!F15 -> 0 | F24: =CPS!G15 -> 0 | G24: =CPS!H15 -> 0 | H24: =CPS!I15 -> 0 | I24: =CPS!J15 -> 0 | ... P24: =CPS!Q15 -> 0
B31: =IF(CPS!C1>0,CPS!C1,"") -> JAN | C31: =IF(CPS!D1>0,CPS!D1,"") -> FEB | D31: =IF(CPS!E1>0,CPS!E1,"") -> MAR | E31: =IF(CPS!F1>0,CPS!F1,"") -> APR | F31: =IF(CPS!G1>0,CPS!G1,"") -> MAY | G31: =IF(CPS!H1>0,CPS!H1,"") -> JUN | H31: =IF(CPS!I1>0,CPS!I1,"") -> JUL | I31: =IF(CPS!J1>0,CPS!J1,"") -> AUG | ... P31: =IF(CPS!Q1>0,CPS!Q1,"") -> MAR'27
A32: =IF(CPS!B2>0,CPS!B2,"") -> Staff | B32: =CPS!C17 -> 0 | C32: =CPS!D17 -> 0 | D32: =CPS!E17 -> 0 | E32: =CPS!F17 -> 0 | F32: =CPS!G17 -> 0 | G32: =CPS!H17 -> 0 | H32: =CPS!I17 -> 0 | I32: =CPS!J17 -> 0 | ... P32: =CPS!Q17 -> 0
A33: =IF(CPS!B3>0,CPS!B3,"") -> Staff AVG | B33: =CPS!C18 -> 0 | C33: =CPS!D18 -> 0 | D33: =CPS!E18 -> 0 | E33: =CPS!F18 -> 0 | F33: =CPS!G18 -> 0 | G33: =CPS!H18 -> 0 | H33: =CPS!I18 -> 0 | I33: =CPS!J18 -> 0 | ... P33: =CPS!Q18 -> 0
A34: =IF(CPS!B4>0,CPS!B4,"") -> Plan | B34: =CPS!C19 -> 0 | C34: =CPS!D19 -> 0 | D34: =CPS!E19 -> 0 | E34: =CPS!F19 -> 0 | F34: =CPS!G19 -> 0 | G34: =CPS!H19 -> 0 | H34: =CPS!I19 -> 0 | I34: =CPS!J19 -> 0 | ... P34: =CPS!Q19 -> 0
B41: =IF(CPS!C31>0,CPS!C31,"") -> Q1 | C41: =IF(CPS!D31>0,CPS!D31,"") -> Q2 | D41: =IF(CPS!E31>0,CPS!E31,"") -> Q3 | E41: =IF(CPS!F31>0,CPS!F31,"") -> Q4 | F41: =IF(CPS!G31>0,CPS!G31,"") -> Q1'27
A42: =IF(CPS!B32>0,CPS!B32,"") -> Staff | B42: =IF(CPS!C32>0,CPS!C32,"") -> 18 | C42: =IF(CPS!D32>0,CPS!D32,"") -> 17 | D42: =IF(CPS!E32>0,CPS!E32,"") -> 17 | E42: =IF(CPS!F32>0,CPS!F32,"") -> 17 | F42: =IF(CPS!G32>0,CPS!G32,"") -> 17
A43: =IF(CPS!B33>0,CPS!B33,"") -> Staff AVG | B43: =IF(CPS!C33>0,CPS!C33,"") -> 17 | C43: =IF(CPS!D33>0,CPS!D33,"") -> 17 | D43: =IF(CPS!E33>0,CPS!E33,"") -> 17 | E43: =IF(CPS!F33>0,CPS!F33,"") -> 17 | F43: =IF(CPS!G33>0,CPS!G33,"") -> 17
A44: =IF(CPS!B34>0,CPS!B34,"") -> Plan | B44: =IF(CPS!C34>0,CPS!C34,"") -> 17 | C44: =IF(CPS!D34>0,CPS!D34,"") -> 17 | D44: =IF(CPS!E34>0,CPS!E34,"") -> 16 | E44: =IF(CPS!F34>0,CPS!F34,"") -> 16 | F44: =IF(CPS!G34>0,CPS!G34,"") -> 15
A45: =IF(CPS!B41>0,CPS!B41,"") -> PAYROLL | B45: =IF(CPS!C41>0,CPS!C41,"") -> 17 | C45: =IF(CPS!D41>0,CPS!D41,"") -> 17 | D45: =IF(CPS!E41>0,CPS!E41,"") -> 16 | E45: =IF(CPS!F41>0,CPS!F41,"") -> 16 | F45: =IF(CPS!G41>0,CPS!G41,"") -> 15
A46: =IF(CPS!B45>0,CPS!B45,"") -> CONTRACTOR | B46: =IF(CPS!C45>0,CPS!C45,"") | C46: =IF(CPS!D45>0,CPS!D45,"") | D46: =IF(CPS!E45>0,CPS!E45,"") | E46: =IF(CPS!F45>0,CPS!F45,"") | F46: =IF(CPS!G45>0,CPS!G45,"")
A47: =IF(CPS!B49>0,CPS!B49,"") -> OUTSOURCE | B47: =IF(CPS!C49>0,CPS!C49,"") | C47: =IF(CPS!D49>0,CPS!D49,"") | D47: =IF(CPS!E49>0,CPS!E49,"") | E47: =IF(CPS!F49>0,CPS!F49,"") | F47: =IF(CPS!G49>0,CPS!G49,"")
A51: =CPS!A66 -> Business Development & Partnerships | B51: =CPS!C61 -> JAN | C51: =CPS!D61 -> FEB | D51: =CPS!E61 -> MAR | E51: =CPS!F61 -> APR | F51: =CPS!G61 -> MAY | G51: =CPS!H61 -> JUN | H51: =CPS!I61 -> JUL | I51: =CPS!J61 -> AUG | ... P51: =CPS!Q61 -> MAR'27
A52: =CPS!B66 -> Staff | B52: =CPS!C66 -> 12 | C52: =CPS!D66 -> 12 | D52: =CPS!E66 -> 12 | E52: =CPS!F66 -> 11 | F52: =CPS!G66 -> 11 | G52: =CPS!H66 -> 11 | H52: =CPS!I66 -> 11 | ... P52: =CPS!Q66 -> 11
A53: =CPS!B67 -> Plan | B53: =CPS!C67 -> 11.25 | C53: =CPS!D67 -> 11.35 | D53: =CPS!E67 -> 11.05 | E53: =CPS!F67 -> 11.4 | F53: =CPS!G67 -> 11.5 | G53: =CPS!H67 -> 11.4 | H53: =CPS!I67 -> 10.2 | ... P53: =CPS!Q67 -> 8.2
A61: =CPS!A68 -> Product Commercialization | B61: =CPS!C61 -> JAN | C61: =CPS!D61 -> FEB | D61: =CPS!E61 -> MAR | E61: =CPS!F61 -> APR | F61: =CPS!G61 -> MAY | G61: =CPS!H61 -> JUN | H61: =CPS!I61 -> JUL | I61: =CPS!J61 -> AUG | ... P61: =CPS!Q61 -> MAR'27
A62: =CPS!B68 -> Staff | B62: =CPS!C68 -> 5 | C62: =CPS!D68 -> 5 | D62: =CPS!E68 -> 5 | E62: =CPS!F68 -> 5 | F62: =CPS!G68 -> 5 | G62: =CPS!H68 -> 5 | H62: =CPS!I68 -> 5 | ... P62: =CPS!Q68 -> 5
A63: =CPS!B69 -> Plan | B63: =CPS!C69 -> 4.6 | C63: =CPS!D69 -> 4.6 | D63: =CPS!E69 -> 4.6 | E63: =CPS!F69 -> 5 | F63: =CPS!G69 -> 5 | G63: =CPS!H69 -> 5 | H63: =CPS!I69 -> 5 | ... P63: =CPS!Q69 -> 5
B151: =CPS!C1 -> JAN | C151: =CPS!D1 -> FEB | D151: =CPS!E1 -> MAR | E151: =CPS!F1 -> APR | F151: =CPS!G1 -> MAY | G151: =CPS!H1 -> JUN | H151: =CPS!I1 -> JUL | I151: =CPS!J1 -> AUG | ... P151: =CPS!Q1 -> MAR'27
A152: =CPS!B6 -> % Plan | B152: =CPS!C6 -> 0.9361 | C152: =CPS!D6 -> 0.9417 | D152: =CPS!E6 -> 0.925 | E152: =CPS!F6 -> 1.0235 | F152: =CPS!G6 -> 1.0294 | G152: =CPS!H6 -> 1.0235 | H152: =CPS!I6 -> 0.9529 | ... P152: =CPS!Q6 -> 0.8353
A153: =CPS!B7 -> Available FTE | B153: =CPS!C7 -> 1 | C153: =CPS!D7 -> 1 | D153: =CPS!E7 -> 1 | E153: =CPS!F7 -> 0 | F153: =CPS!G7 -> 0 | G153: =CPS!H7 -> 0 | H153: =CPS!I7 -> 1 | ... P153: =CPS!Q7 -> 3

Sheet PSE
B1: Type | C1: JAN | D1: FEB | E1: MAR | F1: APR | G1: MAY | H1: JUN | I1: JUL | J1: AUG | K1: SEP | L1: OCT | M1: NOV | N1: DEC | O1: JAN'27 | P1: FEB'27 | Q1: MAR'27
A2: PSE | B2: Staff | C2: 45 | D2: 45 | E2: 45 | F2: 48 | G2: 48 | H2: 48 | I2: 48 | J2: 48 | K2: 48 | L2: 48 | M2: 48 | N2: 48 | O2: 48 | P2: 48 | Q2: 48
A3: PSE | B3: Staff AVG | C3: 47 | D3: 47 | E3: 47 | F3: 47 | G3: 47 | H3: 47 | I3: 47 | J3: 47 | K3: 47 | L3: 47 | M3: 47 | N3: 47 | O3: 47 | P3: 47 | Q3: 47
A4: PSE | B4: Plan | C4: 40 | D4: 42 | E4: 44 | F4: 45 | G4: 47 | H4: 44 | I4: 45 | J4: 45 | K4: 45 | L4: 42 | M4: 41 | N4: 41 | O4: 32 | P4: 32 | Q4: 32
B6: % Plan | C6: 0.8978 | D6: 0.9413 | E6: 0.9882 | F6: 0.9465 | G6: 0.9746 | H6: 0.9148 | I6: 0.9398 | J6: 0.9283 | K6: 0.9388 | L6: 0.8685 | M6: 0.8542 | N6: 0.8542 | O6: 0.6594 | P6: 0.6594 | Q6: 0.6594
B7: Available FTE | C7: 5 | D7: 3 | E7: 1 | F7: 3 | G7: 1 | H7: 4 | I7: 3 | J7: 3 | K7: 3 | L7: 6 | M7: 7 | N7: 7 | O7: 16 | P7: 16 | Q7: 16
A9: Staff | B9: PAYROLL | C9: 28 | D9: 28 | E9: 27 | F9: 28 | G9: 28 | H9: 28 | I9: 28 | J9: 28 | K9: 28 | L9: 28 | M9: 28 | N9: 28 | O9: 28 | P9: 28 | Q9: 28
A10: Staff AVG | B10: PAYROLL | C10: 28 | D10: 28 | E10: 28 | F10: 28 | G10: 28 | H10: 28 | I10: 28 | J10: 28 | K10: 28 | L10: 28 | M10: 28 | N10: 28 | O10: 28 | P10: 28 | Q10: 28
A11: Plan | B11: PAYROLL | C11: 24 | D11: 26 | E11: 26 | F11: 27 | G11: 27 | H11: 25 | I11: 27 | J11: 26 | K11: 26 | L11: 25 | M11: 24 | N11: 24 | O11: 19 | P11: 19 | Q11: 19
A13: Staff | B13: CONTRACTOR | C13: 17 | D13: 17 | E13: 17 | F13: 17 | G13: 17 | H13: 17 | I13: 17 | J13: 17 | K13: 17 | L13: 17 | M13: 17 | N13: 17 | O13: 17 | P13: 17 | Q13: 17
A14: Staff AVG | B14: CONTRACTOR | C14: 17 | D14: 17 | E14: 17 | F14: 17 | G14: 17 | H14: 17 | I14: 17 | J14: 17 | K14: 17 | L14: 17 | M14: 17 | N14: 17 | O14: 17 | P14: 17 | Q14: 17
A15: Plan | B15: CONTRACTOR | C15: 16 | D15: 16 | E15: 18 | F15: 17 | G15: 17 | H15: 16 | I15: 16 | J15: 16 | K15: 16 | L15: 15 | M15: 15 | N15: 15 | O15: 13 | P15: 13 | Q15: 13
A17: Staff | B17: OUTSOURCE | C17: 0 | D17: 0 | E17: 1 | F17: 3 | G17: 3 | H17: 3 | I17: 3 | J17: 3 | K17: 3 | L17: 3 | M17: 3 | N17: 3 | O17: 3 | P17: 3 | Q17: 3
A18: Staff AVG | B18: OUTSOURCE | C18: 2 | D18: 2 | E18: 2 | F18: 2 | G18: 2 | H18: 2 | I18: 2 | J18: 2 | K18: 2 | L18: 2 | M18: 2 | N18: 2 | O18: 2 | P18: 2 | Q18: 2
A19: Plan | B19: OUTSOURCE | C19: 0 | D19: 0 | E19: 0 | F19: 1 | G19: 3 | H19: 3 | I19: 3 | J19: 3 | K19: 3 | L19: 2 | M19: 2 | N19: 2 | O19: 0 | P19: 0 | Q19: 0
B31: Type | C31: Q1 | D31: Q2 | E31: Q3 | F31: Q4 | G31: Q1'27
A32: PSE | B32: Staff | C32: 45 | D32: 48 | E32: 48 | F32: 48 | G32: 48
A33: PSE | B33: Staff AVG | C33: 47 | D33: 48 | E33: 48 | F33: 48 | G33: 48
A34: PSE | B34: Plan | C34: 42 | D34: 45 | E34: 45 | F34: 41 | G34: 38
C35: 0.0576 | D35: 0.0547 | E35: 0.0644 | F35: 0.141 | G35: 0.2108
B36: % Plan | C36: 0.9424 | D36: 0.9453 | E36: 0.9356 | F36: 0.859 | G36: 0.7892
B37: Available FTE | C37: 3 | D37: 3 | E37: 3 | F37: 7 | G37: 10
A39: Staff | B39: PAYROLL | C39: 28 | D39: 28 | E39: 28 | F39: 28 | G39: 28
A40: Staff AVG | B40: PAYROLL | C40: 28 | D40: 28 | E40: 28 | F40: 28 | G40: 28
A41: Plan | B41: PAYROLL | C41: 26 | D41: 27 | E41: 26 | F41: 24 | G41: 22
A43: Staff | B43: CONTRACTOR | C43: 17 | D43: 17 | E43: 17 | F43: 17 | G43: 17
A44: Staff AVG | B44: CONTRACTOR | C44: 17 | D44: 17 | E44: 17 | F44: 17 | G44: 17
A45: Plan | B45: CONTRACTOR | C45: 17 | D45: 17 | E45: 16 | F45: 15 | G45: 14
A47: Staff | B47: OUTSOURCE | C47: 0 | D47: 3 | E47: 3 | F47: 3 | G47: 3
A48: Staff AVG | B48: OUTSOURCE | C48: 2 | D48: 2 | E48: 2 | F48: 2 | G48: 2
A49: Plan | B49: OUTSOURCE | C49: 0 | D49: 2 | E49: 3 | F49: 2 | G49: 1
A61: Section | C61: JAN | D61: FEB | E61: MAR | F61: APR | G61: MAY | H61: JUN | I61: JUL | J61: AUG | K61: SEP | L61: OCT | M61: NOV | N61: DEC | O61: JAN'27 | P61: FEB'27 | Q61: MAR'27
B62: Staff | C62: 45 | D62: 45 | E62: 45 | F62: 48 | G62: 48 | H62: 48 | I62: 48 | J62: 48 | K62: 48 | L62: 48 | M62: 48 | N62: 48 | O62: 48 | P62: 48 | Q62: 48
B63: Plan | C63: 40.4 | D63: 42.36 | E63: 44.47 | F63: 45.43 | G63: 46.78 | H63: 43.91 | I63: 45.11 | J63: 44.56 | K63: 45.06 | L63: 41.69 | M63: 41 | N63: 41 | O63: 31.65 | P63: 31.65 | Q63: 31.65
A64: Platform & Software Engineering | B64: Staff | C64: 1 | D64: 1 | E64: 1 | F64: 1 | G64: 1 | H64: 1 | I64: 1 | J64: 1 | K64: 1 | L64: 1 | M64: 1 | N64: 1 | O64: 1 | P64: 1 | Q64: 1
A65: Platform & Software Engineering | B65: Plan | C65: 1 | D65: 1 | E65: 1 | F65: 1 | G65: 1 | H65: 1 | I65: 1 | J65: 1 | K65: 1 | L65: 1 | M65: 1 | N65: 1 | O65: 1 | P65: 1 | Q65: 1
A66: Platform Engineering | B66: Staff | C66: 5 | D66: 5 | E66: 5 | F66: 6 | G66: 6 | H66: 6 | I66: 6 | J66: 6 | K66: 6 | L66: 6 | M66: 6 | N66: 6 | O66: 6 | P66: 6 | Q66: 6
A67: Platform Engineering | B67: Plan | C67: 5 | D67: 5 | E67: 5 | F67: 6 | G67: 6 | H67: 6 | I67: 6 | J67: 6 | K67: 6 | L67: 6 | M67: 6 | N67: 6 | O67: 6 | P67: 6 | Q67: 6
A68: Platform Engineering:TH | B68: Staff | C68: 4 | D68: 4 | E68: 4 | F68: 5 | G68: 5 | H68: 5 | I68: 5 | J68: 5 | K68: 5 | L68: 5 | M68: 5 | N68: 5 | O68: 5 | P68: 5 | Q68: 5
A69: Platform Engineering:TH | B69: Plan | C69: 4 | D69: 4 | E69: 4 | F69: 5 | G69: 5 | H69: 5 | I69: 5 | J69: 5 | K69: 5 | L69: 5 | M69: 5 | N69: 5 | O69: 5 | P69: 5 | Q69: 5
...

Sheet GraphPSE
B1: =IF(PSE!C1>0,PSE!C1,"") -> JAN | C1: =IF(PSE!D1>0,PSE!D1,"") -> FEB | D1: =IF(PSE!E1>0,PSE!E1,"") -> MAR | E1: =IF(PSE!F1>0,PSE!F1,"") -> APR | F1: =IF(PSE!G1>0,PSE!G1,"") -> MAY | G1: =IF(PSE!H1>0,PSE!H1,"") -> JUN | H1: =IF(PSE!I1>0,PSE!I1,"") -> JUL | I1: =IF(PSE!J1>0,PSE!J1,"") -> AUG | ... P1: =IF(PSE!Q1>0,PSE!Q1,"") -> MAR'27
A2: =IF(PSE!B2>0,PSE!B2,"") -> Staff | B2: =IF(PSE!C2>0,PSE!C2,"") -> 45 | C2: =IF(PSE!D2>0,PSE!D2,"") -> 45 | D2: =IF(PSE!E2>0,PSE!E2,"") -> 45 | E2: =IF(PSE!F2>0,PSE!F2,"") -> 48 | F2: =IF(PSE!G2>0,PSE!G2,"") -> 48 | G2: =IF(PSE!H2>0,PSE!H2,"") -> 48 | H2: =IF(PSE!I2>0,PSE!I2,"") -> 48 | ... P2: =IF(PSE!Q2>0,PSE!Q2,"") -> 48
A3: =IF(PSE!B3>0,PSE!B3,"") -> Staff AVG | B3: =IF(PSE!C3>0,PSE!C3,"") -> 47 | C3: =IF(PSE!D3>0,PSE!D3,"") -> 47 | D3: =IF(PSE!E3>0,PSE!E3,"") -> 47 | E3: =IF(PSE!F3>0,PSE!F3,"") -> 47 | F3: =IF(PSE!G3>0,PSE!G3,"") -> 47 | G3: =IF(PSE!H3>0,PSE!H3,"") -> 47 | H3: =IF(PSE!I3>0,PSE!I3,"") -> 47 | ... P3: =IF(PSE!Q3>0,PSE!Q3,"") -> 47
A4: =IF(PSE!B4>0,PSE!B4,"") -> Plan | B4: =IF(PSE!C4>0,PSE!C4,"") -> 40 | C4: =IF(PSE!D4>0,PSE!D4,"") -> 42 | D4: =IF(PSE!E4>0,PSE!E4,"") -> 44 | E4: =IF(PSE!F4>0,PSE!F4,"") -> 45 | F4: =IF(PSE!G4>0,PSE!G4,"") -> 47 | G4: =IF(PSE!H4>0,PSE!H4,"") -> 44 | H4: =IF(PSE!I4>0,PSE!I4,"") -> 45 | ... P4: =IF(PSE!Q4>0,PSE!Q4,"") -> 32
A5: =IF(PSE!B11>0,PSE!B11,"") -> PAYROLL | B5: =IF(PSE!C11>0,PSE!C11,"") -> 24 | C5: =IF(PSE!D11>0,PSE!D11,"") -> 26 | D5: =IF(PSE!E11>0,PSE!E11,"") -> 26 | E5: =IF(PSE!F11>0,PSE!F11,"") -> 27 | F5: =IF(PSE!G11>0,PSE!G11,"") -> 27 | G5: =IF(PSE!H11>0,PSE!H11,"") -> 25 | H5: =IF(PSE!I11>0,PSE!I11,"") -> 27 | ... P5: =IF(PSE!Q11>0,PSE!Q11,"") -> 19
A6: =IF(PSE!B15>0,PSE!B15,"") -> CONTRACTOR | B6: =IF(PSE!C15>0,PSE!C15,"") -> 16 | C6: =IF(PSE!D15>0,PSE!D15,"") -> 16 | D6: =IF(PSE!E15>0,PSE!E15,"") -> 18 | E6: =IF(PSE!F15>0,PSE!F15,"") -> 17 | F6: =IF(PSE!G15>0,PSE!G15,"") -> 17 | G6: =IF(PSE!H15>0,PSE!H15,"") -> 16 | H6: =IF(PSE!I15>0,PSE!I15,"") -> 16 | ... P6: =IF(PSE!Q15>0,PSE!Q15,"") -> 13
A7: =IF(PSE!B19>0,PSE!B19,"") -> OUTSOURCE | B7: =IF(PSE!C19>0,PSE!C19,"") | C7: =IF(PSE!D19>0,PSE!D19,"") | D7: =IF(PSE!E19>0,PSE!E19,"") | E7: =IF(PSE!F19>0,PSE!F19,"") -> 1 | F7: =IF(PSE!G19>0,PSE!G19,"") -> 3 | G7: =IF(PSE!H19>0,PSE!H19,"") -> 3 | H7: =IF(PSE!I19>0,PSE!I19,"") -> 3 | ... P7: =IF(PSE!Q19>0,PSE!Q19,"")
B11: =IF(PSE!C1>0,PSE!C1,"") -> JAN | C11: =IF(PSE!D1>0,PSE!D1,"") -> FEB | D11: =IF(PSE!E1>0,PSE!E1,"") -> MAR | E11: =IF(PSE!F1>0,PSE!F1,"") -> APR | F11: =IF(PSE!G1>0,PSE!G1,"") -> MAY | G11: =IF(PSE!H1>0,PSE!H1,"") -> JUN | H11: =IF(PSE!I1>0,PSE!I1,"") -> JUL | I11: =IF(PSE!J1>0,PSE!J1,"") -> AUG | ... P11: =IF(PSE!Q1>0,PSE!Q1,"") -> MAR'27
A12: =IF(PSE!B2>0,PSE!B2,"") -> Staff | B12: =IF(PSE!C9>0,PSE!C9,"") -> 28 | C12: =IF(PSE!D9>0,PSE!D9,"") -> 28 | D12: =IF(PSE!E9>0,PSE!E9,"") -> 27 | E12: =IF(PSE!F9>0,PSE!F9,"") -> 28 | F12: =IF(PSE!G9>0,PSE!G9,"") -> 28 | G12: =IF(PSE!H9>0,PSE!H9,"") -> 28 | H12: =IF(PSE!I9>0,PSE!I9,"") -> 28 | I12: =IF(PSE!J9>0,PSE!J9,"") -> 28 | ... P12: =IF(PSE!Q9>0,PSE!Q9,"") -> 28
A13: =IF(PSE!B3>0,PSE!B3,"") -> Staff AVG | B13: =IF(PSE!C10>0,PSE!C10,"") -> 28 | C13: =IF(PSE!D10>0,PSE!D10,"") -> 28 | D13: =IF(PSE!E10>0,PSE!E10,"") -> 28 | E13: =IF(PSE!F10>0,PSE!F10,"") -> 28 | F13: =IF(PSE!G10>0,PSE!G10,"") -> 28 | G13: =IF(PSE!H10>0,PSE!H10,"") -> 28 | H13: =IF(PSE!I10>0,PSE!I10,"") -> 28 | I13: =IF(PSE!J10>0,PSE!J10,"") -> 28 | ... P13: =IF(PSE!Q10>0,PSE!Q10,"") -> 28
A14: =IF(PSE!B4>0,PSE!B4,"") -> Plan | B14: =IF(PSE!C11>0,PSE!C11,"") -> 24 | C14: =IF(PSE!D11>0,PSE!D11,"") -> 26 | D14: =IF(PSE!E11>0,PSE!E11,"") -> 26 | E14: =IF(PSE!F11>0,PSE!F11,"") -> 27 | F14: =IF(PSE!G11>0,PSE!G11,"") -> 27 | G14: =IF(PSE!H11>0,PSE!H11,"") -> 25 | H14: =IF(PSE!I11>0,PSE!I11,"") -> 27 | I14: =IF(PSE!J11>0,PSE!J11,"") -> 26 | ... P14: =IF(PSE!Q11>0,PSE!Q11,"") -> 19
B21: =IF(PSE!C1>0,PSE!C1,"") -> JAN | C21: =IF(PSE!D1>0,PSE!D1,"") -> FEB | D21: =IF(PSE!E1>0,PSE!E1,"") -> MAR | E21: =IF(PSE!F1>0,PSE!F1,"") -> APR | F21: =IF(PSE!G1>0,PSE!G1,"") -> MAY | G21: =IF(PSE!H1>0,PSE!H1,"") -> JUN | H21: =IF(PSE!I1>0,PSE!I1,"") -> JUL | I21: =IF(PSE!J1>0,PSE!J1,"") -> AUG | ... P21: =IF(PSE!Q1>0,PSE!Q1,"") -> MAR'27
A22: =IF(PSE!B2>0,PSE!B2,"") -> Staff | B22: =PSE!C13 -> 17 | C22: =PSE!D13 -> 17 | D22: =PSE!E13 -> 17 | E22: =PSE!F13 -> 17 | F22: =PSE!G13 -> 17 | G22: =PSE!H13 -> 17 | H22: =PSE!I13 -> 17 | I22: =PSE!J13 -> 17 | ... P22: =PSE!Q13 -> 17
A23: =IF(PSE!B3>0,PSE!B3,"") -> Staff AVG | B23: =PSE!C14 -> 17 | C23: =PSE!D14 -> 17 | D23: =PSE!E14 -> 17 | E23: =PSE!F14 -> 17 | F23: =PSE!G14 -> 17 | G23: =PSE!H14 -> 17 | H23: =PSE!I14 -> 17 | I23: =PSE!J14 -> 17 | ... P23: =PSE!Q14 -> 17
A24: =IF(PSE!B4>0,PSE!B4,"") -> Plan | B24: =PSE!C15 -> 16 | C24: =PSE!D15 -> 16 | D24: =PSE!E15 -> 18 | E24: =PSE!F15 -> 17 | F24: =PSE!G15 -> 17 | G24: =PSE!H15 -> 16 | H24: =PSE!I15 -> 16 | I24: =PSE!J15 -> 16 | ... P24: =PSE!Q15 -> 13
B31: =IF(PSE!C1>0,PSE!C1,"") -> JAN | C31: =IF(PSE!D1>0,PSE!D1,"") -> FEB | D31: =IF(PSE!E1>0,PSE!E1,"") -> MAR | E31: =IF(PSE!F1>0,PSE!F1,"") -> APR | F31: =IF(PSE!G1>0,PSE!G1,"") -> MAY | G31: =IF(PSE!H1>0,PSE!H1,"") -> JUN | H31: =IF(PSE!I1>0,PSE!I1,"") -> JUL | I31: =IF(PSE!J1>0,PSE!J1,"") -> AUG | ... P31: =IF(PSE!Q1>0,PSE!Q1,"") -> MAR'27
A32: =IF(PSE!B2>0,PSE!B2,"") -> Staff | B32: =PSE!C17 -> 0 | C32: =PSE!D17 -> 0 | D32: =PSE!E17 -> 1 | E32: =PSE!F17 -> 3 | F32: =PSE!G17 -> 3 | G32: =PSE!H17 -> 3 | H32: =PSE!I17 -> 3 | I32: =PSE!J17 -> 3 | ... P32: =PSE!Q17 -> 3
A33: =IF(PSE!B3>0,PSE!B3,"") -> Staff AVG | B33: =PSE!C18 -> 2 | C33: =PSE!D18 -> 2 | D33: =PSE!E18 -> 2 | E33: =PSE!F18 -> 2 | F33: =PSE!G18 -> 2 | G33: =PSE!H18 -> 2 | H33: =PSE!I18 -> 2 | I33: =PSE!J18 -> 2 | ... P33: =PSE!Q18 -> 2
A34: =IF(PSE!B4>0,PSE!B4,"") -> Plan | B34: =PSE!C19 -> 0 | C34: =PSE!D19 -> 0 | D34: =PSE!E19 -> 0 | E34: =PSE!F19 -> 1 | F34: =PSE!G19 -> 3 | G34: =PSE!H19 -> 3 | H34: =PSE!I19 -> 3 | I34: =PSE!J19 -> 3 | ... P34: =PSE!Q19 -> 0
B41: =IF(PSE!C31>0,PSE!C31,"") -> Q1 | C41: =IF(PSE!D31>0,PSE!D31,"") -> Q2 | D41: =IF(PSE!E31>0,PSE!E31,"") -> Q3 | E41: =IF(PSE!F31>0,PSE!F31,"") -> Q4 | F41: =IF(PSE!G31>0,PSE!G31,"") -> Q1'27
A42: =IF(PSE!B32>0,PSE!B32,"") -> Staff | B42: =IF(PSE!C32>0,PSE!C32,"") -> 45 | C42: =IF(PSE!D32>0,PSE!D32,"") -> 48 | D42: =IF(PSE!E32>0,PSE!E32,"") -> 48 | E42: =IF(PSE!F32>0,PSE!F32,"") -> 48 | F42: =IF(PSE!G32>0,PSE!G32,"") -> 48
A43: =IF(PSE!B33>0,PSE!B33,"") -> Staff AVG | B43: =IF(PSE!C33>0,PSE!C33,"") -> 47 | C43: =IF(PSE!D33>0,PSE!D33,"") -> 48 | D43: =IF(PSE!E33>0,PSE!E33,"") -> 48 | E43: =IF(PSE!F33>0,PSE!F33,"") -> 48 | F43: =IF(PSE!G33>0,PSE!G33,"") -> 48
A44: =IF(PSE!B34>0,PSE!B34,"") -> Plan | B44: =IF(PSE!C34>0,PSE!C34,"") -> 42 | C44: =IF(PSE!D34>0,PSE!D34,"") -> 45 | D44: =IF(PSE!E34>0,PSE!E34,"") -> 45 | E44: =IF(PSE!F34>0,PSE!F34,"") -> 41 | F44: =IF(PSE!G34>0,PSE!G34,"") -> 38
A45: =IF(PSE!B41>0,PSE!B41,"") -> PAYROLL | B45: =IF(PSE!C41>0,PSE!C41,"") -> 26 | C45: =IF(PSE!D41>0,PSE!D41,"") -> 27 | D45: =IF(PSE!E41>0,PSE!E41,"") -> 26 | E45: =IF(PSE!F41>0,PSE!F41,"") -> 24 | F45: =IF(PSE!G41>0,PSE!G41,"") -> 22
A46: =IF(PSE!B45>0,PSE!B45,"") -> CONTRACTOR | B46: =IF(PSE!C45>0,PSE!C45,"") -> 17 | C46: =IF(PSE!D45>0,PSE!D45,"") -> 17 | D46: =IF(PSE!E45>0,PSE!E45,"") -> 16 | E46: =IF(PSE!F45>0,PSE!F45,"") -> 15 | F46: =IF(PSE!G45>0,PSE!G45,"") -> 14
A47: =IF(PSE!B49>0,PSE!B49,"") -> OUTSOURCE | B47: =IF(PSE!C49>0,PSE!C49,"") | C47: =IF(PSE!D49>0,PSE!D49,"") -> 2 | D47: =IF(PSE!E49>0,PSE!E49,"") -> 3 | E47: =IF(PSE!F49>0,PSE!F49,"") -> 2 | F47: =IF(PSE!G49>0,PSE!G49,"") -> 1
A51: =PSE!A66 -> Platform Engineering | B51: =PSE!C61 -> JAN | C51: =PSE!D61 -> FEB | D51: =PSE!E61 -> MAR | E51: =PSE!F61 -> APR | F51: =PSE!G61 -> MAY | G51: =PSE!H61 -> JUN | H51: =PSE!I61 -> JUL | I51: =PSE!J61 -> AUG | ... P51: =PSE!Q61 -> MAR'27
A52: =PSE!B66 -> Staff | B52: =PSE!C66 -> 5 | C52: =PSE!D66 -> 5 | D52: =PSE!E66 -> 5 | E52: =PSE!F66 -> 6 | F52: =PSE!G66 -> 6 | G52: =PSE!H66 -> 6 | H52: =PSE!I66 -> 6 | ... P52: =PSE!Q66 -> 6
A53: =PSE!B67 -> Plan | B53: =PSE!C67 -> 5 | C53: =PSE!D67 -> 5 | D53: =PSE!E67 -> 5 | E53: =PSE!F67 -> 6 | F53: =PSE!G67 -> 6 | G53: =PSE!H67 -> 6 | H53: =PSE!I67 -> 6 | ... P53: =PSE!Q67 -> 6
A61: =PSE!A72 -> Software Engineering | B61: =PSE!C61 -> JAN | C61: =PSE!D61 -> FEB | D61: =PSE!E61 -> MAR | E61: =PSE!F61 -> APR | F61: =PSE!G61 -> MAY | G61: =PSE!H61 -> JUN | H61: =PSE!I61 -> JUL | I61: =PSE!J61 -> AUG | ... P61: =PSE!Q61 -> MAR'27
A62: =PSE!B72 -> Staff | B62: =PSE!C72 -> 39 | C62: =PSE!D72 -> 39 | D62: =PSE!E72 -> 39 | E62: =PSE!F72 -> 41 | F62: =PSE!G72 -> 41 | G62: =PSE!H72 -> 41 | H62: =PSE!I72 -> 41 | ... P62: =PSE!Q72 -> 41
A63: =PSE!B73 -> Plan | B63: =PSE!C73 -> 34.4 | C63: =PSE!D73 -> 36.36 | D63: =PSE!E73 -> 38.47 | E63: =PSE!F73 -> 38.43 | F63: =PSE!G73 -> 39.78 | G63: =PSE!H73 -> 36.91 | H63: =PSE!I73 -> 38.11 | ... P63: =PSE!Q73 -> 24.65
B151: =PSE!C1 -> JAN | C151: =PSE!D1 -> FEB | D151: =PSE!E1 -> MAR | E151: =PSE!F1 -> APR | F151: =PSE!G1 -> MAY | G151: =PSE!H1 -> JUN | H151: =PSE!I1 -> JUL | I151: =PSE!J1 -> AUG | ... P151: =PSE!Q1 -> MAR'27
A152: =PSE!B6 -> % Plan | B152: =PSE!C6 -> 0.8978 | C152: =PSE!D6 -> 0.9413 | D152: =PSE!E6 -> 0.9882 | E152: =PSE!F6 -> 0.9465 | F152: =PSE!G6 -> 0.9746 | G152: =PSE!H6 -> 0.9148 | H152: =PSE!I6 -> 0.9398 | ... P152: =PSE!Q6 -> 0.6594
A153: =PSE!B7 -> Available FTE | B153: =PSE!C7 -> 5 | C153: =PSE!D7 -> 3 | D153: =PSE!E7 -> 1 | E153: =PSE!F7 -> 3 | F153: =PSE!G7 -> 1 | G153: =PSE!H7 -> 4 | H153: =PSE!I7 -> 3 | ... P153: =PSE!Q7 -> 16

Sheet SD
B1: Type | C1: JAN | D1: FEB | E1: MAR | F1: APR | G1: MAY | H1: JUN | I1: JUL | J1: AUG | K1: SEP | L1: OCT | M1: NOV | N1: DEC | O1: JAN'27 | P1: FEB'27 | Q1: MAR'27
A2: SD | B2: Staff | C2: 43 | D2: 45 | E2: 46 | F2: 46 | G2: 46 | H2: 46 | I2: 46 | J2: 46 | K2: 46 | L2: 46 | M2: 46 | N2: 46 | O2: 46 | P2: 46 | Q2: 46
A3: SD | B3: Staff AVG | C3: 46 | D3: 46 | E3: 46 | F3: 46 | G3: 46 | H3: 46 | I3: 46 | J3: 46 | K3: 46 | L3: 46 | M3: 46 | N3: 46 | O3: 46 | P3: 46 | Q3: 46
A4: SD | B4: Plan | C4: 40 | D4: 46 | E4: 48 | F4: 44 | G4: 46 | H4: 46 | I4: 48 | J4: 46 | K4: 45 | L4: 42 | M4: 42 | N4: 42 | O4: 32 | P4: 32 | Q4: 32
B6: % Plan | C6: 0.9409 | D6: 1.0187 | E6: 1.0399 | F6: 0.9508 | G6: 1.0045 | H6: 1.0102 | I6: 1.0387 | J6: 1.0035 | K6: 0.9871 | L6: 0.9239 | M6: 0.9109 | N6: 0.9022 | O6: 0.7044 | P6: 0.6979 | Q6: 0.6979
B7: Available FTE | C7: 3 | D7: -1 | E7: -2 | F7: 2 | G7: 0 | H7: 0 | I7: -2 | J7: 0 | K7: 1 | L7: 4 | M7: 4 | N7: 4 | O7: 14 | P7: 14 | Q7: 14
A9: Staff | B9: PAYROLL | C9: 35 | D9: 35 | E9: 35 | F9: 35 | G9: 35 | H9: 35 | I9: 35 | J9: 35 | K9: 35 | L9: 35 | M9: 35 | N9: 35 | O9: 35 | P9: 35 | Q9: 35
A10: Staff AVG | B10: PAYROLL | C10: 35 | D10: 35 | E10: 35 | F10: 35 | G10: 35 | H10: 35 | I10: 35 | J10: 35 | K10: 35 | L10: 35 | M10: 35 | N10: 35 | O10: 35 | P10: 35 | Q10: 35
A11: Plan | B11: PAYROLL | C11: 33 | D11: 35 | E11: 36 | F11: 33 | G11: 34 | H11: 34 | I11: 33 | J11: 32 | K11: 31 | L11: 30 | M11: 30 | N11: 29 | O11: 23 | P11: 23 | Q11: 23
A13: Staff | B13: CONTRACTOR | C13: 2 | D13: 2 | E13: 2 | F13: 2 | G13: 2 | H13: 2 | I13: 2 | J13: 2 | K13: 2 | L13: 2 | M13: 2 | N13: 2 | O13: 2 | P13: 2 | Q13: 2
A14: Staff AVG | B14: CONTRACTOR | C14: 2 | D14: 2 | E14: 2 | F14: 2 | G14: 2 | H14: 2 | I14: 2 | J14: 2 | K14: 2 | L14: 2 | M14: 2 | N14: 2 | O14: 2 | P14: 2 | Q14: 2
A15: Plan | B15: CONTRACTOR | C15: 2 | D15: 2 | E15: 2 | F15: 2 | G15: 2 | H15: 2 | I15: 2 | J15: 2 | K15: 2 | L15: 2 | M15: 2 | N15: 2 | O15: 2 | P15: 2 | Q15: 2
A17: Staff | B17: OUTSOURCE | C17: 6 | D17: 8 | E17: 9 | F17: 9 | G17: 9 | H17: 9 | I17: 9 | J17: 9 | K17: 9 | L17: 9 | M17: 9 | N17: 9 | O17: 9 | P17: 9 | Q17: 9
A18: Staff AVG | B18: OUTSOURCE | C18: 9 | D18: 9 | E18: 9 | F18: 9 | G18: 9 | H18: 9 | I18: 9 | J18: 9 | K18: 9 | L18: 9 | M18: 9 | N18: 9 | O18: 9 | P18: 9 | Q18: 9
A19: Plan | B19: OUTSOURCE | C19: 6 | D19: 8 | E19: 10 | F19: 9 | G19: 10 | H19: 11 | I19: 12 | J19: 12 | K19: 13 | L19: 10 | M19: 10 | N19: 10 | O19: 7 | P19: 7 | Q19: 7
B31: Type | C31: Q1 | D31: Q2 | E31: Q3 | F31: Q4 | G31: Q1'27
A32: SD | B32: Staff | C32: 45 | D32: 46 | E32: 46 | F32: 46 | G32: 46
A33: SD | B33: Staff AVG | C33: 46 | D33: 46 | E33: 46 | F33: 46 | G33: 46
A34: SD | B34: Plan | C34: 45 | D34: 45 | E34: 46 | F34: 42 | G34: 39
C35: -0.001 | D35: 0.0115 | E35: -0.0098 | F35: 0.0876 | G35: 0.1608
B36: % Plan | C36: 1.001 | D36: 0.9885 | E36: 1.0098 | F36: 0.9124 | G36: 0.8392
B37: Available FTE | C37: 0 | D37: 1 | E37: 0 | F37: 4 | G37: 7
A39: Staff | B39: PAYROLL | C39: 35 | D39: 35 | E39: 35 | F39: 35 | G39: 35
A40: Staff AVG | B40: PAYROLL | C40: 35 | D40: 35 | E40: 35 | F40: 35 | G40: 35
A41: Plan | B41: PAYROLL | C41: 35 | D41: 34 | E41: 32 | F41: 30 | G41: 27
A43: Staff | B43: CONTRACTOR | C43: 2 | D43: 2 | E43: 2 | F43: 2 | G43: 2
A44: Staff AVG | B44: CONTRACTOR | C44: 2 | D44: 2 | E44: 2 | F44: 2 | G44: 2
A45: Plan | B45: CONTRACTOR | C45: 2 | D45: 2 | E45: 2 | F45: 2 | G45: 2
A47: Staff | B47: OUTSOURCE | C47: 8 | D47: 9 | E47: 9 | F47: 9 | G47: 9
A48: Staff AVG | B48: OUTSOURCE | C48: 9 | D48: 9 | E48: 9 | F48: 9 | G48: 9
A49: Plan | B49: OUTSOURCE | C49: 8 | D49: 10 | E49: 12 | F49: 10 | G49: 9
A61: Section | C61: JAN | D61: FEB | E61: MAR | F61: APR | G61: MAY | H61: JUN | I61: JUL | J61: AUG | K61: SEP | L61: OCT | M61: NOV | N61: DEC | O61: JAN'27 | P61: FEB'27 | Q61: MAR'27
B62: Staff | C62: 43 | D62: 45 | E62: 46 | F62: 46 | G62: 46 | H62: 46 | I62: 46 | J62: 46 | K62: 46 | L62: 46 | M62: 46 | N62: 46 | O62: 46 | P62: 46 | Q62: 46
B63: Plan | C63: 34.0775 | D63: 38.525 | E63: 40.52 | F63: 36.765 | G63: 39.62 | H63: 39.775 | I63: 40.58375 | J63: 38.89325 | K63: 38.45575 | L63: 35.5495 | M63: 34.5825 | N63: 33.2575 | O63: 24.42125 | P63: 24.12125 | Q63: 24.12125
A64: Solution Delivery | B64: Staff | C64: 1 | D64: 1 | E64: 1 | F64: 1 | G64: 1 | H64: 1 | I64: 1 | J64: 1 | K64: 1 | L64: 1 | M64: 1 | N64: 1 | O64: 1 | P64: 1 | Q64: 1
A65: Solution Delivery | B65: Plan | C65: 1 | D65: 1 | E65: 1 | F65: 1 | G65: 1 | H65: 1 | I65: 1 | J65: 1 | K65: 1 | L65: 1 | M65: 1 | N65: 1 | O65: 1 | P65: 1 | Q65: 1
A66: Design | B66: Staff | C66: 4 | D66: 4 | E66: 4 | F66: 4 | G66: 4 | H66: 4 | I66: 4 | J66: 4 | K66: 4 | L66: 4 | M66: 4 | N66: 4 | O66: 4 | P66: 4 | Q66: 4
A67: Design | B67: Plan | C67: 3.0625 | D67: 3.85 | E67: 3.65 | F67: 3.3 | G67: 4.025 | H67: 4.025 | I67: 3.98125 | J67: 3.29375 | K67: 2.93125 | L67: 2.7125 | M67: 2.5875 | N67: 2.3875 | O67: 1.28125 | P67: 1.03125 | Q67: 1.03125
A68: Data Technology | B68: Staff | C68: 7 | D68: 7 | E68: 7 | F68: 7 | G68: 7 | H68: 7 | I68: 7 | J68: 7 | K68: 7 | L68: 7 | M68: 7 | N68: 7 | O68: 7 | P68: 7 | Q68: 7
A69: Data Technology | B69: Plan | C69: 7.075 | D69: 7.225 | E69: 6.865 | F69: 6.12 | G69: 5.7075 | H69: 6.4125 | I69: 5.8625 | J69: 5.6325 | K69: 5.6325 | L69: 5.295 | M69: 5.145 | N69: 5.145 | O69: 4.315 | P69: 4.315 | Q69: 4.315
...

Sheet GraphSD
B1: =IF(SD!C1>0,SD!C1,"") -> JAN | C1: =IF(SD!D1>0,SD!D1,"") -> FEB | D1: =IF(SD!E1>0,SD!E1,"") -> MAR | E1: =IF(SD!F1>0,SD!F1,"") -> APR | F1: =IF(SD!G1>0,SD!G1,"") -> MAY | G1: =IF(SD!H1>0,SD!H1,"") -> JUN | H1: =IF(SD!I1>0,SD!I1,"") -> JUL | I1: =IF(SD!J1>0,SD!J1,"") -> AUG | ... P1: =IF(SD!Q1>0,SD!Q1,"") -> MAR'27
A2: =IF(SD!B2>0,SD!B2,"") -> Staff | B2: =IF(SD!C2>0,SD!C2,"") -> 43 | C2: =IF(SD!D2>0,SD!D2,"") -> 45 | D2: =IF(SD!E2>0,SD!E2,"") -> 46 | E2: =IF(SD!F2>0,SD!F2,"") -> 46 | F2: =IF(SD!G2>0,SD!G2,"") -> 46 | G2: =IF(SD!H2>0,SD!H2,"") -> 46 | H2: =IF(SD!I2>0,SD!I2,"") -> 46 | ... P2: =IF(SD!Q2>0,SD!Q2,"") -> 46
A3: =IF(SD!B3>0,SD!B3,"") -> Staff AVG | B3: =IF(SD!C3>0,SD!C3,"") -> 46 | C3: =IF(SD!D3>0,SD!D3,"") -> 46 | D3: =IF(SD!E3>0,SD!E3,"") -> 46 | E3: =IF(SD!F3>0,SD!F3,"") -> 46 | F3: =IF(SD!G3>0,SD!G3,"") -> 46 | G3: =IF(SD!H3>0,SD!H3,"") -> 46 | H3: =IF(SD!I3>0,SD!I3,"") -> 46 | ... P3: =IF(SD!Q3>0,SD!Q3,"") -> 46
A4: =IF(SD!B4>0,SD!B4,"") -> Plan | B4: =IF(SD!C4>0,SD!C4,"") -> 40 | C4: =IF(SD!D4>0,SD!D4,"") -> 46 | D4: =IF(SD!E4>0,SD!E4,"") -> 48 | E4: =IF(SD!F4>0,SD!F4,"") -> 44 | F4: =IF(SD!G4>0,SD!G4,"") -> 46 | G4: =IF(SD!H4>0,SD!H4,"") -> 46 | H4: =IF(SD!I4>0,SD!I4,"") -> 48 | ... P4: =IF(SD!Q4>0,SD!Q4,"") -> 32
A5: =IF(SD!B11>0,SD!B11,"") -> PAYROLL | B5: =IF(SD!C11>0,SD!C11,"") -> 33 | C5: =IF(SD!D11>0,SD!D11,"") -> 35 | D5: =IF(SD!E11>0,SD!E11,"") -> 36 | E5: =IF(SD!F11>0,SD!F11,"") -> 33 | F5: =IF(SD!G11>0,SD!G11,"") -> 34 | G5: =IF(SD!H11>0,SD!H11,"") -> 34 | H5: =IF(SD!I11>0,SD!I11,"") -> 33 | ... P5: =IF(SD!Q11>0,SD!Q11,"") -> 23
A6: =IF(SD!B15>0,SD!B15,"") -> CONTRACTOR | B6: =IF(SD!C15>0,SD!C15,"") -> 2 | C6: =IF(SD!D15>0,SD!D15,"") -> 2 | D6: =IF(SD!E15>0,SD!E15,"") -> 2 | E6: =IF(SD!F15>0,SD!F15,"") -> 2 | F6: =IF(SD!G15>0,SD!G15,"") -> 2 | G6: =IF(SD!H15>0,SD!H15,"") -> 2 | H6: =IF(SD!I15>0,SD!I15,"") -> 2 | ... P6: =IF(SD!Q15>0,SD!Q15,"") -> 2
A7: =IF(SD!B19>0,SD!B19,"") -> OUTSOURCE | B7: =IF(SD!C19>0,SD!C19,"") -> 6 | C7: =IF(SD!D19>0,SD!D19,"") -> 8 | D7: =IF(SD!E19>0,SD!E19,"") -> 10 | E7: =IF(SD!F19>0,SD!F19,"") -> 9 | F7: =IF(SD!G19>0,SD!G19,"") -> 10 | G7: =IF(SD!H19>0,SD!H19,"") -> 11 | H7: =IF(SD!I19>0,SD!I19,"") -> 12 | ... P7: =IF(SD!Q19>0,SD!Q19,"") -> 7
B11: =IF(SD!C1>0,SD!C1,"") -> JAN | C11: =IF(SD!D1>0,SD!D1,"") -> FEB | D11: =IF(SD!E1>0,SD!E1,"") -> MAR | E11: =IF(SD!F1>0,SD!F1,"") -> APR | F11: =IF(SD!G1>0,SD!G1,"") -> MAY | G11: =IF(SD!H1>0,SD!H1,"") -> JUN | H11: =IF(SD!I1>0,SD!I1,"") -> JUL | I11: =IF(SD!J1>0,SD!J1,"") -> AUG | ... P11: =IF(SD!Q1>0,SD!Q1,"") -> MAR'27
A12: =IF(SD!B2>0,SD!B2,"") -> Staff | B12: =IF(SD!C9>0,SD!C9,"") -> 35 | C12: =IF(SD!D9>0,SD!D9,"") -> 35 | D12: =IF(SD!E9>0,SD!E9,"") -> 35 | E12: =IF(SD!F9>0,SD!F9,"") -> 35 | F12: =IF(SD!G9>0,SD!G9,"") -> 35 | G12: =IF(SD!H9>0,SD!H9,"") -> 35 | H12: =IF(SD!I9>0,SD!I9,"") -> 35 | I12: =IF(SD!J9>0,SD!J9,"") -> 35 | ... P12: =IF(SD!Q9>0,SD!Q9,"") -> 35
A13: =IF(SD!B3>0,SD!B3,"") -> Staff AVG | B13: =IF(SD!C10>0,SD!C10,"") -> 35 | C13: =IF(SD!D10>0,SD!D10,"") -> 35 | D13: =IF(SD!E10>0,SD!E10,"") -> 35 | E13: =IF(SD!F10>0,SD!F10,"") -> 35 | F13: =IF(SD!G10>0,SD!G10,"") -> 35 | G13: =IF(SD!H10>0,SD!H10,"") -> 35 | H13: =IF(SD!I10>0,SD!I10,"") -> 35 | I13: =IF(SD!J10>0,SD!J10,"") -> 35 | ... P13: =IF(SD!Q10>0,SD!Q10,"") -> 35
A14: =IF(SD!B4>0,SD!B4,"") -> Plan | B14: =IF(SD!C11>0,SD!C11,"") -> 33 | C14: =IF(SD!D11>0,SD!D11,"") -> 35 | D14: =IF(SD!E11>0,SD!E11,"") -> 36 | E14: =IF(SD!F11>0,SD!F11,"") -> 33 | F14: =IF(SD!G11>0,SD!G11,"") -> 34 | G14: =IF(SD!H11>0,SD!H11,"") -> 34 | H14: =IF(SD!I11>0,SD!I11,"") -> 33 | I14: =IF(SD!J11>0,SD!J11,"") -> 32 | ... P14: =IF(SD!Q11>0,SD!Q11,"") -> 23
B21: =IF(SD!C1>0,SD!C1,"") -> JAN | C21: =IF(SD!D1>0,SD!D1,"") -> FEB | D21: =IF(SD!E1>0,SD!E1,"") -> MAR | E21: =IF(SD!F1>0,SD!F1,"") -> APR | F21: =IF(SD!G1>0,SD!G1,"") -> MAY | G21: =IF(SD!H1>0,SD!H1,"") -> JUN | H21: =IF(SD!I1>0,SD!I1,"") -> JUL | I21: =IF(SD!J1>0,SD!J1,"") -> AUG | ... P21: =IF(SD!Q1>0,SD!Q1,"") -> MAR'27
A22: =IF(SD!B2>0,SD!B2,"") -> Staff | B22: =IF(SD!C13>0,SD!C13,"") -> 2 | C22: =IF(SD!D13>0,SD!D13,"") -> 2 | D22: =IF(SD!E13>0,SD!E13,"") -> 2 | E22: =IF(SD!F13>0,SD!F13,"") -> 2 | F22: =IF(SD!G13>0,SD!G13,"") -> 2 | G22: =IF(SD!H13>0,SD!H13,"") -> 2 | H22: =IF(SD!I13>0,SD!I13,"") -> 2 | I22: =IF(SD!J13>0,SD!J13,"") -> 2 | ... P22: =IF(SD!Q13>0,SD!Q13,"") -> 2
A23: =IF(SD!B3>0,SD!B3,"") -> Staff AVG | B23: =IF(SD!C14>0,SD!C14,"") -> 2 | C23: =IF(SD!D14>0,SD!D14,"") -> 2 | D23: =IF(SD!E14>0,SD!E14,"") -> 2 | E23: =IF(SD!F14>0,SD!F14,"") -> 2 | F23: =IF(SD!G14>0,SD!G14,"") -> 2 | G23: =IF(SD!H14>0,SD!H14,"") -> 2 | H23: =IF(SD!I14>0,SD!I14,"") -> 2 | I23: =IF(SD!J14>0,SD!J14,"") -> 2 | ... P23: =IF(SD!Q14>0,SD!Q14,"") -> 2
A24: =IF(SD!B4>0,SD!B4,"") -> Plan | B24: =IF(SD!C15>0,SD!C15,"") -> 2 | C24: =IF(SD!D15>0,SD!D15,"") -> 2 | D24: =IF(SD!E15>0,SD!E15,"") -> 2 | E24: =IF(SD!F15>0,SD!F15,"") -> 2 | F24: =IF(SD!G15>0,SD!G15,"") -> 2 | G24: =IF(SD!H15>0,SD!H15,"") -> 2 | H24: =IF(SD!I15>0,SD!I15,"") -> 2 | I24: =IF(SD!J15>0,SD!J15,"") -> 2 | ... P24: =IF(SD!Q15>0,SD!Q15,"") -> 2
B31: =IF(SD!C1>0,SD!C1,"") -> JAN | C31: =IF(SD!D1>0,SD!D1,"") -> FEB | D31: =IF(SD!E1>0,SD!E1,"") -> MAR | E31: =IF(SD!F1>0,SD!F1,"") -> APR | F31: =IF(SD!G1>0,SD!G1,"") -> MAY | G31: =IF(SD!H1>0,SD!H1,"") -> JUN | H31: =IF(SD!I1>0,SD!I1,"") -> JUL | I31: =IF(SD!J1>0,SD!J1,"") -> AUG | ... P31: =IF(SD!Q1>0,SD!Q1,"") -> MAR'27
A32: =IF(SD!B2>0,SD!B2,"") -> Staff | B32: =IF(SD!C17>0,SD!C17,"") -> 6 | C32: =IF(SD!D17>0,SD!D17,"") -> 8 | D32: =IF(SD!E17>0,SD!E17,"") -> 9 | E32: =IF(SD!F17>0,SD!F17,"") -> 9 | F32: =IF(SD!G17>0,SD!G17,"") -> 9 | G32: =IF(SD!H17>0,SD!H17,"") -> 9 | H32: =IF(SD!I17>0,SD!I17,"") -> 9 | I32: =IF(SD!J17>0,SD!J17,"") -> 9 | ... P32: =IF(SD!Q17>0,SD!Q17,"") -> 9
A33: =IF(SD!B3>0,SD!B3,"") -> Staff AVG | B33: =IF(SD!C18>0,SD!C18,"") -> 9 | C33: =IF(SD!D18>0,SD!D18,"") -> 9 | D33: =IF(SD!E18>0,SD!E18,"") -> 9 | E33: =IF(SD!F18>0,SD!F18,"") -> 9 | F33: =IF(SD!G18>0,SD!G18,"") -> 9 | G33: =IF(SD!H18>0,SD!H18,"") -> 9 | H33: =IF(SD!I18>0,SD!I18,"") -> 9 | I33: =IF(SD!J18>0,SD!J18,"") -> 9 | ... P33: =IF(SD!Q18>0,SD!Q18,"") -> 9
A34: =IF(SD!B4>0,SD!B4,"") -> Plan | B34: =IF(SD!C19>0,SD!C19,"") -> 6 | C34: =IF(SD!D19>0,SD!D19,"") -> 8 | D34: =IF(SD!E19>0,SD!E19,"") -> 10 | E34: =IF(SD!F19>0,SD!F19,"") -> 9 | F34: =IF(SD!G19>0,SD!G19,"") -> 10 | G34: =IF(SD!H19>0,SD!H19,"") -> 11 | H34: =IF(SD!I19>0,SD!I19,"") -> 12 | I34: =IF(SD!J19>0,SD!J19,"") -> 12 | ... P34: =IF(SD!Q19>0,SD!Q19,"") -> 7
B41: =IF(SD!C31>0,SD!C31,"") -> Q1 | C41: =IF(SD!D31>0,SD!D31,"") -> Q2 | D41: =IF(SD!E31>0,SD!E31,"") -> Q3 | E41: =IF(SD!F31>0,SD!F31,"") -> Q4 | F41: =IF(SD!G31>0,SD!G31,"") -> Q1'27
A42: =IF(SD!B32>0,SD!B32,"") -> Staff | B42: =IF(SD!C32>0,SD!C32,"") -> 45 | C42: =IF(SD!D32>0,SD!D32,"") -> 46 | D42: =IF(SD!E32>0,SD!E32,"") -> 46 | E42: =IF(SD!F32>0,SD!F32,"") -> 46 | F42: =IF(SD!G32>0,SD!G32,"") -> 46
A43: =IF(SD!B33>0,SD!B33,"") -> Staff AVG | B43: =IF(SD!C33>0,SD!C33,"") -> 46 | C43: =IF(SD!D33>0,SD!D33,"") -> 46 | D43: =IF(SD!E33>0,SD!E33,"") -> 46 | E43: =IF(SD!F33>0,SD!F33,"") -> 46 | F43: =IF(SD!G33>0,SD!G33,"") -> 46
A44: =IF(SD!B34>0,SD!B34,"") -> Plan | B44: =IF(SD!C34>0,SD!C34,"") -> 45 | C44: =IF(SD!D34>0,SD!D34,"") -> 45 | D44: =IF(SD!E34>0,SD!E34,"") -> 46 | E44: =IF(SD!F34>0,SD!F34,"") -> 42 | F44: =IF(SD!G34>0,SD!G34,"") -> 39
A45: =IF(SD!B41>0,SD!B41,"") -> PAYROLL | B45: =IF(SD!C41>0,SD!C41,"") -> 35 | C45: =IF(SD!D41>0,SD!D41,"") -> 34 | D45: =IF(SD!E41>0,SD!E41,"") -> 32 | E45: =IF(SD!F41>0,SD!F41,"") -> 30 | F45: =IF(SD!G41>0,SD!G41,"") -> 27
A46: =IF(SD!B45>0,SD!B45,"") -> CONTRACTOR | B46: =IF(SD!C45>0,SD!C45,"") -> 2 | C46: =IF(SD!D45>0,SD!D45,"") -> 2 | D46: =IF(SD!E45>0,SD!E45,"") -> 2 | E46: =IF(SD!F45>0,SD!F45,"") -> 2 | F46: =IF(SD!G45>0,SD!G45,"") -> 2
A47: =IF(SD!B49>0,SD!B49,"") -> OUTSOURCE | B47: =IF(SD!C49>0,SD!C49,"") -> 8 | C47: =IF(SD!D49>0,SD!D49,"") -> 10 | D47: =IF(SD!E49>0,SD!E49,"") -> 12 | E47: =IF(SD!F49>0,SD!F49,"") -> 10 | F47: =IF(SD!G49>0,SD!G49,"") -> 9
A51: =SD!A66 -> Design | B51: =SD!C$61 -> JAN | C51: =SD!D$61 -> FEB | D51: =SD!E$61 -> MAR | E51: =SD!F$61 -> APR | F51: =SD!G$61 -> MAY | G51: =SD!H$61 -> JUN | H51: =SD!I$61 -> JUL | I51: =SD!J$61 -> AUG | ... P51: =SD!Q$61 -> MAR'27
A52: =SD!B66 -> Staff | B52: =SD!C66 -> 4 | C52: =SD!D66 -> 4 | D52: =SD!E66 -> 4 | E52: =SD!F66 -> 4 | F52: =SD!G66 -> 4 | G52: =SD!H66 -> 4 | H52: =SD!I66 -> 4 | ... P52: =SD!Q66 -> 4
A53: =SD!B67 -> Plan | B53: =SD!C67 -> 3.0625 | C53: =SD!D67 -> 3.85 | D53: =SD!E67 -> 3.65 | E53: =SD!F67 -> 3.3 | F53: =SD!G67 -> 4.025 | G53: =SD!H67 -> 4.025 | H53: =SD!I67 -> 3.98125 | ... P53: =SD!Q67 -> 1.03125
A61: =SD!A68 -> Data Technology | B61: =SD!C$61 -> JAN | C61: =SD!D$61 -> FEB | D61: =SD!E$61 -> MAR | E61: =SD!F$61 -> APR | F61: =SD!G$61 -> MAY | G61: =SD!H$61 -> JUN | H61: =SD!I$61 -> JUL | I61: =SD!J$61 -> AUG | ... P61: =SD!Q$61 -> MAR'27
A62: =SD!B68 -> Staff | B62: =SD!C68 -> 7 | C62: =SD!D68 -> 7 | D62: =SD!E68 -> 7 | E62: =SD!F68 -> 7 | F62: =SD!G68 -> 7 | G62: =SD!H68 -> 7 | H62: =SD!I68 -> 7 | ... P62: =SD!Q68 -> 7
A63: =SD!B69 -> Plan | B63: =SD!C69 -> 7.075 | C63: =SD!D69 -> 7.225 | D63: =SD!E69 -> 6.865 | E63: =SD!F69 -> 6.12 | F63: =SD!G69 -> 5.7075 | G63: =SD!H69 -> 6.4125 | H63: =SD!I69 -> 5.8625 | ... P63: =SD!Q69 -> 4.315
A71: =SD!A74 -> Solution Architecture | B71: =SD!C$61 -> JAN | C71: =SD!D$61 -> FEB | D71: =SD!E$61 -> MAR | E71: =SD!F$61 -> APR | F71: =SD!G$61 -> MAY | G71: =SD!H$61 -> JUN | H71: =SD!I$61 -> JUL | I71: =SD!J$61 -> AUG | ... P71: =SD!Q$61 -> MAR'27
A72: =SD!B74 -> Staff | B72: =SD!C74 -> 4 | C72: =SD!D74 -> 4 | D72: =SD!E74 -> 4 | E72: =SD!F74 -> 4 | F72: =SD!G74 -> 4 | G72: =SD!H74 -> 4 | H72: =SD!I74 -> 4 | ... P72: =SD!Q74 -> 4
A73: =SD!B75 -> Plan | B73: =SD!C75 -> 3.3 | C73: =SD!D75 -> 4.375 | D73: =SD!E75 -> 4.325 | E73: =SD!F75 -> 3.9 | F73: =SD!G75 -> 3.515 | G73: =SD!H75 -> 3.465 | H73: =SD!I75 -> 3.365 | ... P73: =SD!Q75 -> 2.78
A81: =SD!A76 -> Site Reliability Engineering | B81: =SD!C$61 -> JAN | C81: =SD!D$61 -> FEB | D81: =SD!E$61 -> MAR | E81: =SD!F$61 -> APR | F81: =SD!G$61 -> MAY | G81: =SD!H$61 -> JUN | H81: =SD!I$61 -> JUL | I81: =SD!J$61 -> AUG | ... P81: =SD!Q$61 -> MAR'27
A82: =SD!B76 -> Staff | B82: =SD!C76 -> 2 | C82: =SD!D76 -> 2 | D82: =SD!E76 -> 2 | E82: =SD!F76 -> 2 | F82: =SD!G76 -> 2 | G82: =SD!H76 -> 2 | H82: =SD!I76 -> 2 | ... P82: =SD!Q76 -> 2
A83: =SD!B77 -> Plan | B83: =SD!C77 -> 3.385 | C83: =SD!D77 -> 3.075 | D83: =SD!E77 -> 4.22 | E83: =SD!F77 -> 2.655 | F83: =SD!G77 -> 2.685 | G83: =SD!H77 -> 2.465 | H83: =SD!I77 -> 2.315 | ... P83: =SD!Q77 -> 1.455
A91: =SD!A78 -> Cyber Security | B91: =SD!C$61 -> JAN | C91: =SD!D$61 -> FEB | D91: =SD!E$61 -> MAR | E91: =SD!F$61 -> APR | F91: =SD!G$61 -> MAY | G91: =SD!H$61 -> JUN | H91: =SD!I$61 -> JUL | I91: =SD!J$61 -> AUG | ... P91: =SD!Q$61 -> MAR'27
A92: =SD!B78 -> Staff | B92: =SD!C78 -> 3 | C92: =SD!D78 -> 3 | D92: =SD!E78 -> 3 | E92: =SD!F78 -> 3 | F92: =SD!G78 -> 3 | G92: =SD!H78 -> 3 | H92: =SD!I78 -> 3 | ... P92: =SD!Q78 -> 3
...

Sheet AIC
B1: Type | C1: JAN | D1: FEB | E1: MAR | F1: APR | G1: MAY | H1: JUN | I1: JUL | J1: AUG | K1: SEP | L1: OCT | M1: NOV | N1: DEC | O1: JAN'27 | P1: FEB'27 | Q1: MAR'27
A2: AIC | B2: Staff | C2: 24 | D2: 23 | E2: 22 | F2: 21 | G2: 20 | H2: 20 | I2: 19 | J2: 19 | K2: 19 | L2: 19 | M2: 19 | N2: 19 | O2: 19 | P2: 19 | Q2: 19
A3: AIC | B3: Staff AVG | C3: 20 | D3: 20 | E3: 20 | F3: 20 | G3: 20 | H3: 20 | I3: 20 | J3: 20 | K3: 20 | L3: 20 | M3: 20 | N3: 20 | O3: 20 | P3: 20 | Q3: 20
